Workbook

Sheet Tabelle1
A1: Indexfeld | B1: Begriff | C1: Anzahl | D1: Thesaurusbegriff01 | E1: Thesaurusbegriff02 | F1: Thesaurusbegriff03 | G1: Thesaurusbegriff04 | H1: Thesaurusbegriff05 | I1: Thesaurusbegriff06 | J1: Thesaurusbegriff07 | K1: Thesaurusbegriff08 | L1: Thesaurusbegriff09 | M1: Thesaurusbegriff10 | N1: Thesaurusbegriff11 | O1: Thesaurusbegriff12 | P1: Thesaurusbegriff13 | Q1: Thesaurusbegriff14 | R1: Thesaurusbegriff15 | S1: Notation01 | T1: Notation02 | U1: Notation03 | V1: Notation04 | W1: Notation05 | X1: Notation06 | Y1: Notation07 | Z1: Notation08 | AA1: Notation09 | AB1: Notation10 | AC1: Notation11 | AD1: Notation12 | AE1: Notation13 | AF1: Notation14 | AG1: Notation15
A2: 5240 | B2: alla greca | D2: Einband alla greca | E2: Fester Einband | F2: Heftung auf versenkte Bünde | G2: Holz (Deckel) | H2: Leder (Bezug) | S2: =IF(D2="","",INDEX(Tabelle2!$A$2:$C$241,MATCH(D2,Tabelle2!$C$2:$C$241,0),1)) -> BNDG-X699 | T2: =IF(E2="","",INDEX(Tabelle2!$A$2:$C$241,MATCH(E2,Tabelle2!$C$2:$C$241,0),1)) -> BNDG-A532 | U2: =IF(F2="","",INDEX(Tabelle2!$A$2:$C$241,MATCH(F2,Tabelle2!$C$2:$C$241,0),1)) -> BNDG-B118 | V2: =IF(G2="","",INDEX(Tabelle2!$A$2:$C$241,MATCH(G2,Tabelle2!$C$2:$C$241,0),1)) -> BNDG-D174 | W2: =IF(H2="","",INDEX(Tabelle2!$A$2:$C$241,MATCH(H2,Tabelle2!$C$2:$C$241,0),1)) -> BNDG-E702 | X2: =IF(I2="","",INDEX(Tabelle2!$A$2:$C$241,MATCH(I2,Tabelle2!$C$2:$C$241,0),1)) | Y2: =IF(J2="","",INDEX(Tabelle2!$A$2:$C$241,MATCH(J2,Tabelle2!$C$2:$C$241,0),1)) | Z2: =IF(K2="","",INDEX(Tabelle2!$A$2:$C$241,MATCH(K2,Tabelle2!$C$2:$C$241,0),1)) | ... AG2: =IF(R2="","",INDEX(Tabelle2!$A$2:$C$241,MATCH(R2,Tabelle2!$C$2:$C$241,0),1))
A3: 5240 | B3: Arabeskeneinband | D3: Einband vorhanden | E3: Verzierung vorhanden | S3: =IF(D3="","",INDEX(Tabelle2!$A$2:$C$241,MATCH(D3,Tabelle2!$C$2:$C$241,0),1)) -> BNDG-A239 | T3: =IF(E3="","",INDEX(Tabelle2!$A$2:$C$241,MATCH(E3,Tabelle2!$C$2:$C$241,0),1)) -> BNDG-G607 | U3: =IF(F3="","",INDEX(Tabelle2!$A$2:$C$241,MATCH(F3,Tabelle2!$C$2:$C$241,0),1)) | V3: =IF(G3="","",INDEX(Tabelle2!$A$2:$C$241,MATCH(G3,Tabelle2!$C$2:$C$241,0),1)) | W3: =IF(H3="","",INDEX(Tabelle2!$A$2:$C$241,MATCH(H3,Tabelle2!$C$2:$C$241,0),1)) | X3: =IF(I3="","",INDEX(Tabelle2!$A$2:$C$241,MATCH(I3,Tabelle2!$C$2:$C$241,0),1)) | Y3: =IF(J3="","",INDEX(Tabelle2!$A$2:$C$241,MATCH(J3,Tabelle2!$C$2:$C$241,0),1)) | Z3: =IF(K3="","",INDEX(Tabelle2!$A$2:$C$241,MATCH(K3,Tabelle2!$C$2:$C$241,0),1)) | ... AG3: =IF(R3="","",INDEX(Tabelle2!$A$2:$C$241,MATCH(R3,Tabelle2!$C$2:$C$241,0),1))
A4: 5240 | B4: Barockeinband | D4: Einband vorhanden | S4: =IF(D4="","",INDEX(Tabelle2!$A$2:$C$241,MATCH(D4,Tabelle2!$C$2:$C$241,0),1)) -> BNDG-A239 | T4: =IF(E4="","",INDEX(Tabelle2!$A$2:$C$241,MATCH(E4,Tabelle2!$C$2:$C$241,0),1)) | U4: =IF(F4="","",INDEX(Tabelle2!$A$2:$C$241,MATCH(F4,Tabelle2!$C$2:$C$241,0),1)) | V4: =IF(G4="","",INDEX(Tabelle2!$A$2:$C$241,MATCH(G4,Tabelle2!$C$2:$C$241,0),1)) | W4: =IF(H4="","",INDEX(Tabelle2!$A$2:$C$241,MATCH(H4,Tabelle2!$C$2:$C$241,0),1)) | X4: =IF(I4="","",INDEX(Tabelle2!$A$2:$C$241,MATCH(I4,Tabelle2!$C$2:$C$241,0),1)) | Y4: =IF(J4="","",INDEX(Tabelle2!$A$2:$C$241,MATCH(J4,Tabelle2!$C$2:$C$241,0),1)) | Z4: =IF(K4="","",INDEX(Tabelle2!$A$2:$C$241,MATCH(K4,Tabelle2!$C$2:$C$241,0),1)) | ... AG4: =IF(R4="","",INDEX(Tabelle2!$A$2:$C$241,MATCH(R4,Tabelle2!$C$2:$C$241,0),1))
A5: 5240 | B5: Barock-Einband | C5: 6 | D5: Einband vorhanden | S5: =IF(D5="","",INDEX(Tabelle2!$A$2:$C$241,MATCH(D5,Tabelle2!$C$2:$C$241,0),1)) -> BNDG-A239 | T5: =IF(E5="","",INDEX(Tabelle2!$A$2:$C$241,MATCH(E5,Tabelle2!$C$2:$C$241,0),1)) | U5: =IF(F5="","",INDEX(Tabelle2!$A$2:$C$241,MATCH(F5,Tabelle2!$C$2:$C$241,0),1)) | V5: =IF(G5="","",INDEX(Tabelle2!$A$2:$C$241,MATCH(G5,Tabelle2!$C$2:$C$241,0),1)) | W5: =IF(H5="","",INDEX(Tabelle2!$A$2:$C$241,MATCH(H5,Tabelle2!$C$2:$C$241,0),1)) | X5: =IF(I5="","",INDEX(Tabelle2!$A$2:$C$241,MATCH(I5,Tabelle2!$C$2:$C$241,0),1)) | Y5: =IF(J5="","",INDEX(Tabelle2!$A$2:$C$241,MATCH(J5,Tabelle2!$C$2:$C$241,0),1)) | Z5: =IF(K5="","",INDEX(Tabelle2!$A$2:$C$241,MATCH(K5,Tabelle2!$C$2:$C$241,0),1)) | ... AG5: =IF(R5="","",INDEX(Tabelle2!$A$2:$C$241,MATCH(R5,Tabelle2!$C$2:$C$241,0),1))
A6: 5240 | B6: Barockeinband | C6: 6 | D6: Einband vorhanden | S6: =IF(D6="","",INDEX(Tabelle2!$A$2:$C$241,MATCH(D6,Tabelle2!$C$2:$C$241,0),1)) -> BNDG-A239 | T6: =IF(E6="","",INDEX(Tabelle2!$A$2:$C$241,MATCH(E6,Tabelle2!$C$2:$C$241,0),1)) | U6: =IF(F6="","",INDEX(Tabelle2!$A$2:$C$241,MATCH(F6,Tabelle2!$C$2:$C$241,0),1)) | V6: =IF(G6="","",INDEX(Tabelle2!$A$2:$C$241,MATCH(G6,Tabelle2!$C$2:$C$241,0),1)) | W6: =IF(H6="","",INDEX(Tabelle2!$A$2:$C$241,MATCH(H6,Tabelle2!$C$2:$C$241,0),1)) | X6: =IF(I6="","",INDEX(Tabelle2!$A$2:$C$241,MATCH(I6,Tabelle2!$C$2:$C$241,0),1)) | Y6: =IF(J6="","",INDEX(Tabelle2!$A$2:$C$241,MATCH(J6,Tabelle2!$C$2:$C$241,0),1)) | Z6: =IF(K6="","",INDEX(Tabelle2!$A$2:$C$241,MATCH(K6,Tabelle2!$C$2:$C$241,0),1)) | ... AG6: =IF(R6="","",INDEX(Tabelle2!$A$2:$C$241,MATCH(R6,Tabelle2!$C$2:$C$241,0),1))
A7: 5240 | B7: Barockeinband / moderner Einband | D7: Einband vorhanden | S7: =IF(D7="","",INDEX(Tabelle2!$A$2:$C$241,MATCH(D7,Tabelle2!$C$2:$C$241,0),1)) -> BNDG-A239 | T7: =IF(E7="","",INDEX(Tabelle2!$A$2:$C$241,MATCH(E7,Tabelle2!$C$2:$C$241,0),1)) | U7: =IF(F7="","",INDEX(Tabelle2!$A$2:$C$241,MATCH(F7,Tabelle2!$C$2:$C$241,0),1)) | V7: =IF(G7="","",INDEX(Tabelle2!$A$2:$C$241,MATCH(G7,Tabelle2!$C$2:$C$241,0),1)) | W7: =IF(H7="","",INDEX(Tabelle2!$A$2:$C$241,MATCH(H7,Tabelle2!$C$2:$C$241,0),1)) | X7: =IF(I7="","",INDEX(Tabelle2!$A$2:$C$241,MATCH(I7,Tabelle2!$C$2:$C$241,0),1)) | Y7: =IF(J7="","",INDEX(Tabelle2!$A$2:$C$241,MATCH(J7,Tabelle2!$C$2:$C$241,0),1)) | Z7: =IF(K7="","",INDEX(Tabelle2!$A$2:$C$241,MATCH(K7,Tabelle2!$C$2:$C$241,0),1)) | ... AG7: =IF(R7="","",INDEX(Tabelle2!$A$2:$C$241,MATCH(R7,Tabelle2!$C$2:$C$241,0),1))
A8: 5240 | B8: Barockeinband mit Einzel- und Rollenstempeln | C8: 2 | D8: Blindprägeeinband | E8: Fester Einband ohne Klappe | F8: Heftung | G8: Leder (Bezug) | H8: Bezug vorhanden | I8: Einzelstempel (Blindprägung) | J8: Rolle (Blindprägung) | S8: =IF(D8="","",INDEX(Tabelle2!$A$2:$C$241,MATCH(D8,Tabelle2!$C$2:$C$241,0),1)) -> BNDG-X717 | T8: =IF(E8="","",INDEX(Tabelle2!$A$2:$C$241,MATCH(E8,Tabelle2!$C$2:$C$241,0),1)) -> BNDG-A206 | U8: =IF(F8="","",INDEX(Tabelle2!$A$2:$C$241,MATCH(F8,Tabelle2!$C$2:$C$241,0),1)) -> BNDG-B859 | V8: =IF(G8="","",INDEX(Tabelle2!$A$2:$C$241,MATCH(G8,Tabelle2!$C$2:$C$241,0),1)) -> BNDG-E702 | W8: =IF(H8="","",INDEX(Tabelle2!$A$2:$C$241,MATCH(H8,Tabelle2!$C$2:$C$241,0),1)) -> BNDG-F468 | X8: =IF(I8="","",INDEX(Tabelle2!$A$2:$C$241,MATCH(I8,Tabelle2!$C$2:$C$241,0),1)) -> BNDG-G882 | Y8: =IF(J8="","",INDEX(Tabelle2!$A$2:$C$241,MATCH(J8,Tabelle2!$C$2:$C$241,0),1)) -> BNDG-G525 | Z8: =IF(K8="","",INDEX(Tabelle2!$A$2:$C$241,MATCH(K8,Tabelle2!$C$2:$C$241,0),1)) | ... AG8: =IF(R8="","",INDEX(Tabelle2!$A$2:$C$241,MATCH(R8,Tabelle2!$C$2:$C$241,0),1))
A9: 5240 | B9: Bemalter Einband | C9: 1 | D9: Einband vorhanden | E9: Bemalung | S9: =IF(D9="","",INDEX(Tabelle2!$A$2:$C$241,MATCH(D9,Tabelle2!$C$2:$C$241,0),1)) -> BNDG-A239 | T9: =IF(E9="","",INDEX(Tabelle2!$A$2:$C$241,MATCH(E9,Tabelle2!$C$2:$C$241,0),1)) -> BNDG-G948 | U9: =IF(F9="","",INDEX(Tabelle2!$A$2:$C$241,MATCH(F9,Tabelle2!$C$2:$C$241,0),1)) | V9: =IF(G9="","",INDEX(Tabelle2!$A$2:$C$241,MATCH(G9,Tabelle2!$C$2:$C$241,0),1)) | W9: =IF(H9="","",INDEX(Tabelle2!$A$2:$C$241,MATCH(H9,Tabelle2!$C$2:$C$241,0),1)) | X9: =IF(I9="","",INDEX(Tabelle2!$A$2:$C$241,MATCH(I9,Tabelle2!$C$2:$C$241,0),1)) | Y9: =IF(J9="","",INDEX(Tabelle2!$A$2:$C$241,MATCH(J9,Tabelle2!$C$2:$C$241,0),1)) | Z9: =IF(K9="","",INDEX(Tabelle2!$A$2:$C$241,MATCH(K9,Tabelle2!$C$2:$C$241,0),1)) | ... AG9: =IF(R9="","",INDEX(Tabelle2!$A$2:$C$241,MATCH(R9,Tabelle2!$C$2:$C$241,0),1))
A10: 5240 | B10: Beschläge | C10: 1 | D10: Beschlag vorhanden | S10: =IF(D10="","",INDEX(Tabelle2!$A$2:$C$241,MATCH(D10,Tabelle2!$C$2:$C$241,0),1)) -> BNDG-M340 | T10: =IF(E10="","",INDEX(Tabelle2!$A$2:$C$241,MATCH(E10,Tabelle2!$C$2:$C$241,0),1)) | U10: =IF(F10="","",INDEX(Tabelle2!$A$2:$C$241,MATCH(F10,Tabelle2!$C$2:$C$241,0),1)) | V10: =IF(G10="","",INDEX(Tabelle2!$A$2:$C$241,MATCH(G10,Tabelle2!$C$2:$C$241,0),1)) | W10: =IF(H10="","",INDEX(Tabelle2!$A$2:$C$241,MATCH(H10,Tabelle2!$C$2:$C$241,0),1)) | X10: =IF(I10="","",INDEX(Tabelle2!$A$2:$C$241,MATCH(I10,Tabelle2!$C$2:$C$241,0),1)) | Y10: =IF(J10="","",INDEX(Tabelle2!$A$2:$C$241,MATCH(J10,Tabelle2!$C$2:$C$241,0),1)) | Z10: =IF(K10="","",INDEX(Tabelle2!$A$2:$C$241,MATCH(K10,Tabelle2!$C$2:$C$241,0),1)) | ... AG10: =IF(R10="","",INDEX(Tabelle2!$A$2:$C$241,MATCH(R10,Tabelle2!$C$2:$C$241,0),1))
A11: 5240 | B11: besorgter spätgotischer Holzdeckeleinband, teilweise mit braunem Leder bezogen | C11: 1 | D11: Holzdeckeleinband | E11: Fester Einband | F11: Heftung auf Bünde | G11: Holz (Deckel) | H11: Teilweise bezogen | I11: Leder (Bezug) | S11: =IF(D11="","",INDEX(Tabelle2!$A$2:$C$241,MATCH(D11,Tabelle2!$C$2:$C$241,0),1)) -> BNDG-X831 | T11: =IF(E11="","",INDEX(Tabelle2!$A$2:$C$241,MATCH(E11,Tabelle2!$C$2:$C$241,0),1)) -> BNDG-A532 | U11: =IF(F11="","",INDEX(Tabelle2!$A$2:$C$241,MATCH(F11,Tabelle2!$C$2:$C$241,0),1)) -> BNDG-B726 | V11: =IF(G11="","",INDEX(Tabelle2!$A$2:$C$241,MATCH(G11,Tabelle2!$C$2:$C$241,0),1)) -> BNDG-D174 | W11: =IF(H11="","",INDEX(Tabelle2!$A$2:$C$241,MATCH(H11,Tabelle2!$C$2:$C$241,0),1)) -> BNDG-F682 | X11: =IF(I11="","",INDEX(Tabelle2!$A$2:$C$241,MATCH(I11,Tabelle2!$C$2:$C$241,0),1)) -> BNDG-E702 | Y11: =IF(J11="","",INDEX(Tabelle2!$A$2:$C$241,MATCH(J11,Tabelle2!$C$2:$C$241,0),1)) | Z11: =IF(K11="","",INDEX(Tabelle2!$A$2:$C$241,MATCH(K11,Tabelle2!$C$2:$C$241,0),1)) | ... AG11: =IF(R11="","",INDEX(Tabelle2!$A$2:$C$241,MATCH(R11,Tabelle2!$C$2:$C$241,0),1))
A12: 5240 | B12: Beutelbuch | C12: 8 | D12: Beutelbuch | E12: Fester Einband ohne Klappe | F12: Heftung | G12: Holz (Deckel) | H12: Leder (Bezug) | I12: Bezug vorhanden | J12: Bezug über die Kanten hinaus verlängert | S12: =IF(D12="","",INDEX(Tabelle2!$A$2:$C$241,MATCH(D12,Tabelle2!$C$2:$C$241,0),1)) -> BNDG-X774 | T12: =IF(E12="","",INDEX(Tabelle2!$A$2:$C$241,MATCH(E12,Tabelle2!$C$2:$C$241,0),1)) -> BNDG-A206 | U12: =IF(F12="","",INDEX(Tabelle2!$A$2:$C$241,MATCH(F12,Tabelle2!$C$2:$C$241,0),1)) -> BNDG-B859 | V12: =IF(G12="","",INDEX(Tabelle2!$A$2:$C$241,MATCH(G12,Tabelle2!$C$2:$C$241,0),1)) -> BNDG-D174 | W12: =IF(H12="","",INDEX(Tabelle2!$A$2:$C$241,MATCH(H12,Tabelle2!$C$2:$C$241,0),1)) -> BNDG-E702 | X12: =IF(I12="","",INDEX(Tabelle2!$A$2:$C$241,MATCH(I12,Tabelle2!$C$2:$C$241,0),1)) -> BNDG-F468 | Y12: =IF(J12="","",INDEX(Tabelle2!$A$2:$C$241,MATCH(J12,Tabelle2!$C$2:$C$241,0),1)) -> BNDG-F142 | Z12: =IF(K12="","",INDEX(Tabelle2!$A$2:$C$241,MATCH(K12,Tabelle2!$C$2:$C$241,0),1)) | ... AG12: =IF(R12="","",INDEX(Tabelle2!$A$2:$C$241,MATCH(R12,Tabelle2!$C$2:$C$241,0),1))
A13: 5240 | B13: Beutelbuch? | C13: 2 | D13: Einband vorhanden | S13: =IF(D13="","",INDEX(Tabelle2!$A$2:$C$241,MATCH(D13,Tabelle2!$C$2:$C$241,0),1)) -> BNDG-A239 | T13: =IF(E13="","",INDEX(Tabelle2!$A$2:$C$241,MATCH(E13,Tabelle2!$C$2:$C$241,0),1)) | U13: =IF(F13="","",INDEX(Tabelle2!$A$2:$C$241,MATCH(F13,Tabelle2!$C$2:$C$241,0),1)) | V13: =IF(G13="","",INDEX(Tabelle2!$A$2:$C$241,MATCH(G13,Tabelle2!$C$2:$C$241,0),1)) | W13: =IF(H13="","",INDEX(Tabelle2!$A$2:$C$241,MATCH(H13,Tabelle2!$C$2:$C$241,0),1)) | X13: =IF(I13="","",INDEX(Tabelle2!$A$2:$C$241,MATCH(I13,Tabelle2!$C$2:$C$241,0),1)) | Y13: =IF(J13="","",INDEX(Tabelle2!$A$2:$C$241,MATCH(J13,Tabelle2!$C$2:$C$241,0),1)) | Z13: =IF(K13="","",INDEX(Tabelle2!$A$2:$C$241,MATCH(K13,Tabelle2!$C$2:$C$241,0),1)) | ... AG13: =IF(R13="","",INDEX(Tabelle2!$A$2:$C$241,MATCH(R13,Tabelle2!$C$2:$C$241,0),1))
A14: 5240 | B14: Blindprägeband | C14: 2 | D14: Blindprägeeinband | E14: Fester Einband ohne Klappe | F14: Heftung | G14: Leder (Bezug) | H14: Bezug vorhanden | I14: Blindprägung | S14: =IF(D14="","",INDEX(Tabelle2!$A$2:$C$241,MATCH(D14,Tabelle2!$C$2:$C$241,0),1)) -> BNDG-X717 | T14: =IF(E14="","",INDEX(Tabelle2!$A$2:$C$241,MATCH(E14,Tabelle2!$C$2:$C$241,0),1)) -> BNDG-A206 | U14: =IF(F14="","",INDEX(Tabelle2!$A$2:$C$241,MATCH(F14,Tabelle2!$C$2:$C$241,0),1)) -> BNDG-B859 | V14: =IF(G14="","",INDEX(Tabelle2!$A$2:$C$241,MATCH(G14,Tabelle2!$C$2:$C$241,0),1)) -> BNDG-E702 | W14: =IF(H14="","",INDEX(Tabelle2!$A$2:$C$241,MATCH(H14,Tabelle2!$C$2:$C$241,0),1)) -> BNDG-F468 | X14: =IF(I14="","",INDEX(Tabelle2!$A$2:$C$241,MATCH(I14,Tabelle2!$C$2:$C$241,0),1)) -> BNDG-G747 | Y14: =IF(J14="","",INDEX(Tabelle2!$A$2:$C$241,MATCH(J14,Tabelle2!$C$2:$C$241,0),1)) | Z14: =IF(K14="","",INDEX(Tabelle2!$A$2:$C$241,MATCH(K14,Tabelle2!$C$2:$C$241,0),1)) | ... AG14: =IF(R14="","",INDEX(Tabelle2!$A$2:$C$241,MATCH(R14,Tabelle2!$C$2:$C$241,0),1))
A15: 5240 | B15: Blindstempel-Einband | C15: 1 | D15: Blindstempeleinband | E15: Fester Einband ohne Klappe | F15: Heftung | G15: Leder (Bezug) | H15: Bezug vorhanden | I15: Einzelstempel (Blindprägung) | S15: =IF(D15="","",INDEX(Tabelle2!$A$2:$C$241,MATCH(D15,Tabelle2!$C$2:$C$241,0),1)) -> BNDG-X986 | T15: =IF(E15="","",INDEX(Tabelle2!$A$2:$C$241,MATCH(E15,Tabelle2!$C$2:$C$241,0),1)) -> BNDG-A206 | U15: =IF(F15="","",INDEX(Tabelle2!$A$2:$C$241,MATCH(F15,Tabelle2!$C$2:$C$241,0),1)) -> BNDG-B859 | V15: =IF(G15="","",INDEX(Tabelle2!$A$2:$C$241,MATCH(G15,Tabelle2!$C$2:$C$241,0),1)) -> BNDG-E702 | W15: =IF(H15="","",INDEX(Tabelle2!$A$2:$C$241,MATCH(H15,Tabelle2!$C$2:$C$241,0),1)) -> BNDG-F468 | X15: =IF(I15="","",INDEX(Tabelle2!$A$2:$C$241,MATCH(I15,Tabelle2!$C$2:$C$241,0),1)) -> BNDG-G882 | Y15: =IF(J15="","",INDEX(Tabelle2!$A$2:$C$241,MATCH(J15,Tabelle2!$C$2:$C$241,0),1)) | Z15: =IF(K15="","",INDEX(Tabelle2!$A$2:$C$241,MATCH(K15,Tabelle2!$C$2:$C$241,0),1)) | ... AG15: =IF(R15="","",INDEX(Tabelle2!$A$2:$C$241,MATCH(R15,Tabelle2!$C$2:$C$241,0),1))
A16: 5240 | B16: Blindstempeleinband | C16: 9 | D16: Blindstempeleinband | E16: Fester Einband ohne Klappe | F16: Heftung | G16: Leder (Bezug) | H16: Bezug vorhanden | I16: Einzelstempel (Blindprägung) | S16: =IF(D16="","",INDEX(Tabelle2!$A$2:$C$241,MATCH(D16,Tabelle2!$C$2:$C$241,0),1)) -> BNDG-X986 | T16: =IF(E16="","",INDEX(Tabelle2!$A$2:$C$241,MATCH(E16,Tabelle2!$C$2:$C$241,0),1)) -> BNDG-A206 | U16: =IF(F16="","",INDEX(Tabelle2!$A$2:$C$241,MATCH(F16,Tabelle2!$C$2:$C$241,0),1)) -> BNDG-B859 | V16: =IF(G16="","",INDEX(Tabelle2!$A$2:$C$241,MATCH(G16,Tabelle2!$C$2:$C$241,0),1)) -> BNDG-E702 | W16: =IF(H16="","",INDEX(Tabelle2!$A$2:$C$241,MATCH(H16,Tabelle2!$C$2:$C$241,0),1)) -> BNDG-F468 | X16: =IF(I16="","",INDEX(Tabelle2!$A$2:$C$241,MATCH(I16,Tabelle2!$C$2:$C$241,0),1)) -> BNDG-G882 | Y16: =IF(J16="","",INDEX(Tabelle2!$A$2:$C$241,MATCH(J16,Tabelle2!$C$2:$C$241,0),1)) | Z16: =IF(K16="","",INDEX(Tabelle2!$A$2:$C$241,MATCH(K16,Tabelle2!$C$2:$C$241,0),1)) | ... AG16: =IF(R16="","",INDEX(Tabelle2!$A$2:$C$241,MATCH(R16,Tabelle2!$C$2:$C$241,0),1))
A17: 5240 | B17: Blindstempeleinband, spätgotisch, auf Holz | C17: 4 | D17: Blindstempeleinband | E17: Fester Einband ohne Klappe | F17: Heftung | G17: Leder (Bezug) | H17: Bezug vorhanden | I17: Einzelstempel (Blindprägung) | J17: Holz (Deckel) | S17: =IF(D17="","",INDEX(Tabelle2!$A$2:$C$241,MATCH(D17,Tabelle2!$C$2:$C$241,0),1)) -> BNDG-X986 | T17: =IF(E17="","",INDEX(Tabelle2!$A$2:$C$241,MATCH(E17,Tabelle2!$C$2:$C$241,0),1)) -> BNDG-A206 | U17: =IF(F17="","",INDEX(Tabelle2!$A$2:$C$241,MATCH(F17,Tabelle2!$C$2:$C$241,0),1)) -> BNDG-B859 | V17: =IF(G17="","",INDEX(Tabelle2!$A$2:$C$241,MATCH(G17,Tabelle2!$C$2:$C$241,0),1)) -> BNDG-E702 | W17: =IF(H17="","",INDEX(Tabelle2!$A$2:$C$241,MATCH(H17,Tabelle2!$C$2:$C$241,0),1)) -> BNDG-F468 | X17: =IF(I17="","",INDEX(Tabelle2!$A$2:$C$241,MATCH(I17,Tabelle2!$C$2:$C$241,0),1)) -> BNDG-G882 | Y17: =IF(J17="","",INDEX(Tabelle2!$A$2:$C$241,MATCH(J17,Tabelle2!$C$2:$C$241,0),1)) -> BNDG-D174 | Z17: =IF(K17="","",INDEX(Tabelle2!$A$2:$C$241,MATCH(K17,Tabelle2!$C$2:$C$241,0),1)) | ... AG17: =IF(R17="","",INDEX(Tabelle2!$A$2:$C$241,MATCH(R17,Tabelle2!$C$2:$C$241,0),1))
A18: 5240 | B18: Blindstempeleinband, spätmittelalterlich | C18: 1 | D18: Blindstempeleinband | E18: Fester Einband ohne Klappe | F18: Heftung | G18: Leder (Bezug) | H18: Bezug vorhanden | I18: Einzelstempel (Blindprägung) | J18: Holz (Deckel) | S18: =IF(D18="","",INDEX(Tabelle2!$A$2:$C$241,MATCH(D18,Tabelle2!$C$2:$C$241,0),1)) -> BNDG-X986 | T18: =IF(E18="","",INDEX(Tabelle2!$A$2:$C$241,MATCH(E18,Tabelle2!$C$2:$C$241,0),1)) -> BNDG-A206 | U18: =IF(F18="","",INDEX(Tabelle2!$A$2:$C$241,MATCH(F18,Tabelle2!$C$2:$C$241,0),1)) -> BNDG-B859 | V18: =IF(G18="","",INDEX(Tabelle2!$A$2:$C$241,MATCH(G18,Tabelle2!$C$2:$C$241,0),1)) -> BNDG-E702 | W18: =IF(H18="","",INDEX(Tabelle2!$A$2:$C$241,MATCH(H18,Tabelle2!$C$2:$C$241,0),1)) -> BNDG-F468 | X18: =IF(I18="","",INDEX(Tabelle2!$A$2:$C$241,MATCH(I18,Tabelle2!$C$2:$C$241,0),1)) -> BNDG-G882 | Y18: =IF(J18="","",INDEX(Tabelle2!$A$2:$C$241,MATCH(J18,Tabelle2!$C$2:$C$241,0),1)) -> BNDG-D174 | Z18: =IF(K18="","",INDEX(Tabelle2!$A$2:$C$241,MATCH(K18,Tabelle2!$C$2:$C$241,0),1)) | ... AG18: =IF(R18="","",INDEX(Tabelle2!$A$2:$C$241,MATCH(R18,Tabelle2!$C$2:$C$241,0),1))
A19: 5240 | B19: Blindstempeleinband, spätmittelalterlich, braun, auf Holz | C19: 1 | D19: Blindstempeleinband | E19: Fester Einband ohne Klappe | F19: Heftung | G19: Leder (Bezug) | H19: Bezug vorhanden | I19: Einzelstempel (Blindprägung) | J19: Holz (Deckel) | S19: =IF(D19="","",INDEX(Tabelle2!$A$2:$C$241,MATCH(D19,Tabelle2!$C$2:$C$241,0),1)) -> BNDG-X986 | T19: =IF(E19="","",INDEX(Tabelle2!$A$2:$C$241,MATCH(E19,Tabelle2!$C$2:$C$241,0),1)) -> BNDG-A206 | U19: =IF(F19="","",INDEX(Tabelle2!$A$2:$C$241,MATCH(F19,Tabelle2!$C$2:$C$241,0),1)) -> BNDG-B859 | V19: =IF(G19="","",INDEX(Tabelle2!$A$2:$C$241,MATCH(G19,Tabelle2!$C$2:$C$241,0),1)) -> BNDG-E702 | W19: =IF(H19="","",INDEX(Tabelle2!$A$2:$C$241,MATCH(H19,Tabelle2!$C$2:$C$241,0),1)) -> BNDG-F468 | X19: =IF(I19="","",INDEX(Tabelle2!$A$2:$C$241,MATCH(I19,Tabelle2!$C$2:$C$241,0),1)) -> BNDG-G882 | Y19: =IF(J19="","",INDEX(Tabelle2!$A$2:$C$241,MATCH(J19,Tabelle2!$C$2:$C$241,0),1)) -> BNDG-D174 | Z19: =IF(K19="","",INDEX(Tabelle2!$A$2:$C$241,MATCH(K19,Tabelle2!$C$2:$C$241,0),1)) | ... AG19: =IF(R19="","",INDEX(Tabelle2!$A$2:$C$241,MATCH(R19,Tabelle2!$C$2:$C$241,0),1))
A20: 5240 | B20: Brauner Lederband | C20: 1 | D20: Einband vorhanden | E20: Leder (Bezug) | S20: =IF(D20="","",INDEX(Tabelle2!$A$2:$C$241,MATCH(D20,Tabelle2!$C$2:$C$241,0),1)) -> BNDG-A239 | T20: =IF(E20="","",INDEX(Tabelle2!$A$2:$C$241,MATCH(E20,Tabelle2!$C$2:$C$241,0),1)) -> BNDG-E702 | U20: =IF(F20="","",INDEX(Tabelle2!$A$2:$C$241,MATCH(F20,Tabelle2!$C$2:$C$241,0),1)) | V20: =IF(G20="","",INDEX(Tabelle2!$A$2:$C$241,MATCH(G20,Tabelle2!$C$2:$C$241,0),1)) | W20: =IF(H20="","",INDEX(Tabelle2!$A$2:$C$241,MATCH(H20,Tabelle2!$C$2:$C$241,0),1)) | X20: =IF(I20="","",INDEX(Tabelle2!$A$2:$C$241,MATCH(I20,Tabelle2!$C$2:$C$241,0),1)) | Y20: =IF(J20="","",INDEX(Tabelle2!$A$2:$C$241,MATCH(J20,Tabelle2!$C$2:$C$241,0),1)) | Z20: =IF(K20="","",INDEX(Tabelle2!$A$2:$C$241,MATCH(K20,Tabelle2!$C$2:$C$241,0),1)) | ... AG20: =IF(R20="","",INDEX(Tabelle2!$A$2:$C$241,MATCH(R20,Tabelle2!$C$2:$C$241,0),1))
A21: 5240 | B21: Brauner Ledereinband auf Holzdeckeln, Byzantinische Technik | C21: 1 | D21: Einband byzantinischen Typs | E21: Fester Einband | F21: Heftung auf versenkte Bünde | G21: Holz (Deckel) | H21: Leder (Bezug) | I21: Bezug vorhanden | S21: =IF(D21="","",INDEX(Tabelle2!$A$2:$C$241,MATCH(D21,Tabelle2!$C$2:$C$241,0),1)) -> BNDG-X463 | T21: =IF(E21="","",INDEX(Tabelle2!$A$2:$C$241,MATCH(E21,Tabelle2!$C$2:$C$241,0),1)) -> BNDG-A532 | U21: =IF(F21="","",INDEX(Tabelle2!$A$2:$C$241,MATCH(F21,Tabelle2!$C$2:$C$241,0),1)) -> BNDG-B118 | V21: =IF(G21="","",INDEX(Tabelle2!$A$2:$C$241,MATCH(G21,Tabelle2!$C$2:$C$241,0),1)) -> BNDG-D174 | W21: =IF(H21="","",INDEX(Tabelle2!$A$2:$C$241,MATCH(H21,Tabelle2!$C$2:$C$241,0),1)) -> BNDG-E702 | X21: =IF(I21="","",INDEX(Tabelle2!$A$2:$C$241,MATCH(I21,Tabelle2!$C$2:$C$241,0),1)) -> BNDG-F468 | Y21: =IF(J21="","",INDEX(Tabelle2!$A$2:$C$241,MATCH(J21,Tabelle2!$C$2:$C$241,0),1)) | Z21: =IF(K21="","",INDEX(Tabelle2!$A$2:$C$241,MATCH(K21,Tabelle2!$C$2:$C$241,0),1)) | ... AG21: =IF(R21="","",INDEX(Tabelle2!$A$2:$C$241,MATCH(R21,Tabelle2!$C$2:$C$241,0),1))
A22: 5240 | B22: Brauner Ledereinband auf Pappe | C22: 3 | D22: Pappband | E22: Fester Einband | F22: Pappe (Deckel) | G22: Leder (Bezug) | H22: Bezug vorhanden | S22: =IF(D22="","",INDEX(Tabelle2!$A$2:$C$241,MATCH(D22,Tabelle2!$C$2:$C$241,0),1)) -> BNDG-X514 | T22: =IF(E22="","",INDEX(Tabelle2!$A$2:$C$241,MATCH(E22,Tabelle2!$C$2:$C$241,0),1)) -> BNDG-A532 | U22: =IF(F22="","",INDEX(Tabelle2!$A$2:$C$241,MATCH(F22,Tabelle2!$C$2:$C$241,0),1)) -> BNDG-D235 | V22: =IF(G22="","",INDEX(Tabelle2!$A$2:$C$241,MATCH(G22,Tabelle2!$C$2:$C$241,0),1)) -> BNDG-E702 | W22: =IF(H22="","",INDEX(Tabelle2!$A$2:$C$241,MATCH(H22,Tabelle2!$C$2:$C$241,0),1)) -> BNDG-F468 | X22: =IF(I22="","",INDEX(Tabelle2!$A$2:$C$241,MATCH(I22,Tabelle2!$C$2:$C$241,0),1)) | Y22: =IF(J22="","",INDEX(Tabelle2!$A$2:$C$241,MATCH(J22,Tabelle2!$C$2:$C$241,0),1)) | Z22: =IF(K22="","",INDEX(Tabelle2!$A$2:$C$241,MATCH(K22,Tabelle2!$C$2:$C$241,0),1)) | ... AG22: =IF(R22="","",INDEX(Tabelle2!$A$2:$C$241,MATCH(R22,Tabelle2!$C$2:$C$241,0),1))
A23: 5240 | B23: Brauner Ledereinband auf Pappe in der Art eines alla greca-Bandes, aber nicht sehr gelungen | C23: 1 | D23: Pappband | E23: Fester Einband | F23: Pappe (Deckel) | G23: Leder (Bezug) | H23: Heftung auf versenkte Bünde | I23: Bezug vorhanden | S23: =IF(D23="","",INDEX(Tabelle2!$A$2:$C$241,MATCH(D23,Tabelle2!$C$2:$C$241,0),1)) -> BNDG-X514 | T23: =IF(E23="","",INDEX(Tabelle2!$A$2:$C$241,MATCH(E23,Tabelle2!$C$2:$C$241,0),1)) -> BNDG-A532 | U23: =IF(F23="","",INDEX(Tabelle2!$A$2:$C$241,MATCH(F23,Tabelle2!$C$2:$C$241,0),1)) -> BNDG-D235 | V23: =IF(G23="","",INDEX(Tabelle2!$A$2:$C$241,MATCH(G23,Tabelle2!$C$2:$C$241,0),1)) -> BNDG-E702 | W23: =IF(H23="","",INDEX(Tabelle2!$A$2:$C$241,MATCH(H23,Tabelle2!$C$2:$C$241,0),1)) -> BNDG-B118 | X23: =IF(I23="","",INDEX(Tabelle2!$A$2:$C$241,MATCH(I23,Tabelle2!$C$2:$C$241,0),1)) -> BNDG-F468 | Y23: =IF(J23="","",INDEX(Tabelle2!$A$2:$C$241,MATCH(J23,Tabelle2!$C$2:$C$241,0),1)) | Z23: =IF(K23="","",INDEX(Tabelle2!$A$2:$C$241,MATCH(K23,Tabelle2!$C$2:$C$241,0),1)) | ... AG23: =IF(R23="","",INDEX(Tabelle2!$A$2:$C$241,MATCH(R23,Tabelle2!$C$2:$C$241,0),1))
A24: 5240 | B24: Brauner Wildledereinband (auf Pappe) | C24: 1 | D24: Pappband | E24: Fester Einband | F24: Pappe (Deckel) | G24: Rauleder (Bezug) | H24: Bezug vorhanden | S24: =IF(D24="","",INDEX(Tabelle2!$A$2:$C$241,MATCH(D24,Tabelle2!$C$2:$C$241,0),1)) -> BNDG-X514 | T24: =IF(E24="","",INDEX(Tabelle2!$A$2:$C$241,MATCH(E24,Tabelle2!$C$2:$C$241,0),1)) -> BNDG-A532 | U24: =IF(F24="","",INDEX(Tabelle2!$A$2:$C$241,MATCH(F24,Tabelle2!$C$2:$C$241,0),1)) -> BNDG-D235 | V24: =IF(G24="","",INDEX(Tabelle2!$A$2:$C$241,MATCH(G24,Tabelle2!$C$2:$C$241,0),1)) -> BNDG-E672 | W24: =IF(H24="","",INDEX(Tabelle2!$A$2:$C$241,MATCH(H24,Tabelle2!$C$2:$C$241,0),1)) -> BNDG-F468 | X24: =IF(I24="","",INDEX(Tabelle2!$A$2:$C$241,MATCH(I24,Tabelle2!$C$2:$C$241,0),1)) | Y24: =IF(J24="","",INDEX(Tabelle2!$A$2:$C$241,MATCH(J24,Tabelle2!$C$2:$C$241,0),1)) | Z24: =IF(K24="","",INDEX(Tabelle2!$A$2:$C$241,MATCH(K24,Tabelle2!$C$2:$C$241,0),1)) | ... AG24: =IF(R24="","",INDEX(Tabelle2!$A$2:$C$241,MATCH(R24,Tabelle2!$C$2:$C$241,0),1))
A25: 5240 | B25: Broschur | C25: 21 | D25: Broschur | E25: Flexibler Einband | F25: Heftung auf Band | S25: =IF(D25="","",INDEX(Tabelle2!$A$2:$C$241,MATCH(D25,Tabelle2!$C$2:$C$241,0),1)) -> BNDG-X434 | T25: =IF(E25="","",INDEX(Tabelle2!$A$2:$C$241,MATCH(E25,Tabelle2!$C$2:$C$241,0),1)) -> BNDG-A507 | U25: =IF(F25="","",INDEX(Tabelle2!$A$2:$C$241,MATCH(F25,Tabelle2!$C$2:$C$241,0),1)) -> BNDG-B783 | V25: =IF(G25="","",INDEX(Tabelle2!$A$2:$C$241,MATCH(G25,Tabelle2!$C$2:$C$241,0),1)) | W25: =IF(H25="","",INDEX(Tabelle2!$A$2:$C$241,MATCH(H25,Tabelle2!$C$2:$C$241,0),1)) | X25: =IF(I25="","",INDEX(Tabelle2!$A$2:$C$241,MATCH(I25,Tabelle2!$C$2:$C$241,0),1)) | Y25: =IF(J25="","",INDEX(Tabelle2!$A$2:$C$241,MATCH(J25,Tabelle2!$C$2:$C$241,0),1)) | Z25: =IF(K25="","",INDEX(Tabelle2!$A$2:$C$241,MATCH(K25,Tabelle2!$C$2:$C$241,0),1)) | ... AG25: =IF(R25="","",INDEX(Tabelle2!$A$2:$C$241,MATCH(R25,Tabelle2!$C$2:$C$241,0),1))
A26: 5240 | B26: Broschur (Heft 1) | C26: 12 | D26: Broschur | E26: Flexibler Einband | F26: Heftung auf Band | S26: =IF(D26="","",INDEX(Tabelle2!$A$2:$C$241,MATCH(D26,Tabelle2!$C$2:$C$241,0),1)) -> BNDG-X434 | T26: =IF(E26="","",INDEX(Tabelle2!$A$2:$C$241,MATCH(E26,Tabelle2!$C$2:$C$241,0),1)) -> BNDG-A507 | U26: =IF(F26="","",INDEX(Tabelle2!$A$2:$C$241,MATCH(F26,Tabelle2!$C$2:$C$241,0),1)) -> BNDG-B783 | V26: =IF(G26="","",INDEX(Tabelle2!$A$2:$C$241,MATCH(G26,Tabelle2!$C$2:$C$241,0),1)) | W26: =IF(H26="","",INDEX(Tabelle2!$A$2:$C$241,MATCH(H26,Tabelle2!$C$2:$C$241,0),1)) | X26: =IF(I26="","",INDEX(Tabelle2!$A$2:$C$241,MATCH(I26,Tabelle2!$C$2:$C$241,0),1)) | Y26: =IF(J26="","",INDEX(Tabelle2!$A$2:$C$241,MATCH(J26,Tabelle2!$C$2:$C$241,0),1)) | Z26: =IF(K26="","",INDEX(Tabelle2!$A$2:$C$241,MATCH(K26,Tabelle2!$C$2:$C$241,0),1)) | ... AG26: =IF(R26="","",INDEX(Tabelle2!$A$2:$C$241,MATCH(R26,Tabelle2!$C$2:$C$241,0),1))
A27: 5240 | B27: Buchblock, gebunden, im Schuber | C27: 1 | D27: Heftung | S27: =IF(D27="","",INDEX(Tabelle2!$A$2:$C$241,MATCH(D27,Tabelle2!$C$2:$C$241,0),1)) -> BNDG-B859 | T27: =IF(E27="","",INDEX(Tabelle2!$A$2:$C$241,MATCH(E27,Tabelle2!$C$2:$C$241,0),1)) | U27: =IF(F27="","",INDEX(Tabelle2!$A$2:$C$241,MATCH(F27,Tabelle2!$C$2:$C$241,0),1)) | V27: =IF(G27="","",INDEX(Tabelle2!$A$2:$C$241,MATCH(G27,Tabelle2!$C$2:$C$241,0),1)) | W27: =IF(H27="","",INDEX(Tabelle2!$A$2:$C$241,MATCH(H27,Tabelle2!$C$2:$C$241,0),1)) | X27: =IF(I27="","",INDEX(Tabelle2!$A$2:$C$241,MATCH(I27,Tabelle2!$C$2:$C$241,0),1)) | Y27: =IF(J27="","",INDEX(Tabelle2!$A$2:$C$241,MATCH(J27,Tabelle2!$C$2:$C$241,0),1)) | Z27: =IF(K27="","",INDEX(Tabelle2!$A$2:$C$241,MATCH(K27,Tabelle2!$C$2:$C$241,0),1)) | ... AG27: =IF(R27="","",INDEX(Tabelle2!$A$2:$C$241,MATCH(R27,Tabelle2!$C$2:$C$241,0),1))
A28: 5240 | B28: Buchblock, mittelalterlich gebunden, mit Rücken, ohne Decke, im neuzeitlichen Pappschuber | C28: 1 | D28: Einband entfernt (mit Resten eines ursprünglichen Einbands) | S28: =IF(D28="","",INDEX(Tabelle2!$A$2:$C$241,MATCH(D28,Tabelle2!$C$2:$C$241,0),1)) -> BNDG-A180 | T28: =IF(E28="","",INDEX(Tabelle2!$A$2:$C$241,MATCH(E28,Tabelle2!$C$2:$C$241,0),1)) | U28: =IF(F28="","",INDEX(Tabelle2!$A$2:$C$241,MATCH(F28,Tabelle2!$C$2:$C$241,0),1)) | V28: =IF(G28="","",INDEX(Tabelle2!$A$2:$C$241,MATCH(G28,Tabelle2!$C$2:$C$241,0),1)) | W28: =IF(H28="","",INDEX(Tabelle2!$A$2:$C$241,MATCH(H28,Tabelle2!$C$2:$C$241,0),1)) | X28: =IF(I28="","",INDEX(Tabelle2!$A$2:$C$241,MATCH(I28,Tabelle2!$C$2:$C$241,0),1)) | Y28: =IF(J28="","",INDEX(Tabelle2!$A$2:$C$241,MATCH(J28,Tabelle2!$C$2:$C$241,0),1)) | Z28: =IF(K28="","",INDEX(Tabelle2!$A$2:$C$241,MATCH(K28,Tabelle2!$C$2:$C$241,0),1)) | ... AG28: =IF(R28="","",INDEX(Tabelle2!$A$2:$C$241,MATCH(R28,Tabelle2!$C$2:$C$241,0),1))
A29: 5240 | B29: Buchkassette | C29: 1 | D29: Buchkasten | E29: Einband vorhanden | S29: =IF(D29="","",INDEX(Tabelle2!$A$2:$C$241,MATCH(D29,Tabelle2!$C$2:$C$241,0),1)) -> BNDG-X370 | T29: =IF(E29="","",INDEX(Tabelle2!$A$2:$C$241,MATCH(E29,Tabelle2!$C$2:$C$241,0),1)) -> BNDG-A239 | U29: =IF(F29="","",INDEX(Tabelle2!$A$2:$C$241,MATCH(F29,Tabelle2!$C$2:$C$241,0),1)) | V29: =IF(G29="","",INDEX(Tabelle2!$A$2:$C$241,MATCH(G29,Tabelle2!$C$2:$C$241,0),1)) | W29: =IF(H29="","",INDEX(Tabelle2!$A$2:$C$241,MATCH(H29,Tabelle2!$C$2:$C$241,0),1)) | X29: =IF(I29="","",INDEX(Tabelle2!$A$2:$C$241,MATCH(I29,Tabelle2!$C$2:$C$241,0),1)) | Y29: =IF(J29="","",INDEX(Tabelle2!$A$2:$C$241,MATCH(J29,Tabelle2!$C$2:$C$241,0),1)) | Z29: =IF(K29="","",INDEX(Tabelle2!$A$2:$C$241,MATCH(K29,Tabelle2!$C$2:$C$241,0),1)) | ... AG29: =IF(R29="","",INDEX(Tabelle2!$A$2:$C$241,MATCH(R29,Tabelle2!$C$2:$C$241,0),1))
A30: 5240 | B30: Buchkasten | C30: 1 | D30: Buchkasten | E30: Einband vorhanden | S30: =IF(D30="","",INDEX(Tabelle2!$A$2:$C$241,MATCH(D30,Tabelle2!$C$2:$C$241,0),1)) -> BNDG-X370 | T30: =IF(E30="","",INDEX(Tabelle2!$A$2:$C$241,MATCH(E30,Tabelle2!$C$2:$C$241,0),1)) -> BNDG-A239 | U30: =IF(F30="","",INDEX(Tabelle2!$A$2:$C$241,MATCH(F30,Tabelle2!$C$2:$C$241,0),1)) | V30: =IF(G30="","",INDEX(Tabelle2!$A$2:$C$241,MATCH(G30,Tabelle2!$C$2:$C$241,0),1)) | W30: =IF(H30="","",INDEX(Tabelle2!$A$2:$C$241,MATCH(H30,Tabelle2!$C$2:$C$241,0),1)) | X30: =IF(I30="","",INDEX(Tabelle2!$A$2:$C$241,MATCH(I30,Tabelle2!$C$2:$C$241,0),1)) | Y30: =IF(J30="","",INDEX(Tabelle2!$A$2:$C$241,MATCH(J30,Tabelle2!$C$2:$C$241,0),1)) | Z30: =IF(K30="","",INDEX(Tabelle2!$A$2:$C$241,MATCH(K30,Tabelle2!$C$2:$C$241,0),1)) | ... AG30: =IF(R30="","",INDEX(Tabelle2!$A$2:$C$241,MATCH(R30,Tabelle2!$C$2:$C$241,0),1))
A31: 5240 | B31: Buntpapiereinband | C31: 1 | D31: Einband vorhanden | E31: Buntpapier (Bezug) | F31: Bezug vorhanden | S31: =IF(D31="","",INDEX(Tabelle2!$A$2:$C$241,MATCH(D31,Tabelle2!$C$2:$C$241,0),1)) -> BNDG-A239 | T31: =IF(E31="","",INDEX(Tabelle2!$A$2:$C$241,MATCH(E31,Tabelle2!$C$2:$C$241,0),1)) -> BNDG-E851 | U31: =IF(F31="","",INDEX(Tabelle2!$A$2:$C$241,MATCH(F31,Tabelle2!$C$2:$C$241,0),1)) -> BNDG-F468 | V31: =IF(G31="","",INDEX(Tabelle2!$A$2:$C$241,MATCH(G31,Tabelle2!$C$2:$C$241,0),1)) | W31: =IF(H31="","",INDEX(Tabelle2!$A$2:$C$241,MATCH(H31,Tabelle2!$C$2:$C$241,0),1)) | X31: =IF(I31="","",INDEX(Tabelle2!$A$2:$C$241,MATCH(I31,Tabelle2!$C$2:$C$241,0),1)) | Y31: =IF(J31="","",INDEX(Tabelle2!$A$2:$C$241,MATCH(J31,Tabelle2!$C$2:$C$241,0),1)) | Z31: =IF(K31="","",INDEX(Tabelle2!$A$2:$C$241,MATCH(K31,Tabelle2!$C$2:$C$241,0),1)) | ... AG31: =IF(R31="","",INDEX(Tabelle2!$A$2:$C$241,MATCH(R31,Tabelle2!$C$2:$C$241,0),1))
A32: 5240 | B32: Byzantinischer Holzdeckeleinband | C32: 1 | D32: Byzantinischer Einband | E32: Fester Einband | F32: Heftung auf versenkte Bünde | G32: Holz (Deckel) | H32: Leder (Bezug) | I32: Bezug vorhanden | S32: =IF(D32="","",INDEX(Tabelle2!$A$2:$C$241,MATCH(D32,Tabelle2!$C$2:$C$241,0),1)) -> BNDG-X558 | T32: =IF(E32="","",INDEX(Tabelle2!$A$2:$C$241,MATCH(E32,Tabelle2!$C$2:$C$241,0),1)) -> BNDG-A532 | U32: =IF(F32="","",INDEX(Tabelle2!$A$2:$C$241,MATCH(F32,Tabelle2!$C$2:$C$241,0),1)) -> BNDG-B118 | V32: =IF(G32="","",INDEX(Tabelle2!$A$2:$C$241,MATCH(G32,Tabelle2!$C$2:$C$241,0),1)) -> BNDG-D174 | W32: =IF(H32="","",INDEX(Tabelle2!$A$2:$C$241,MATCH(H32,Tabelle2!$C$2:$C$241,0),1)) -> BNDG-E702 | X32: =IF(I32="","",INDEX(Tabelle2!$A$2:$C$241,MATCH(I32,Tabelle2!$C$2:$C$241,0),1)) -> BNDG-F468 | Y32: =IF(J32="","",INDEX(Tabelle2!$A$2:$C$241,MATCH(J32,Tabelle2!$C$2:$C$241,0),1)) | Z32: =IF(K32="","",INDEX(Tabelle2!$A$2:$C$241,MATCH(K32,Tabelle2!$C$2:$C$241,0),1)) | ... AG32: =IF(R32="","",INDEX(Tabelle2!$A$2:$C$241,MATCH(R32,Tabelle2!$C$2:$C$241,0),1))
A33: 5240 | B33: Copert | D33: Kopert | E33: Flexibler Einband mit Klappe | F33: Pergament (Deckel) | G33: Heftung | S33: =IF(D33="","",INDEX(Tabelle2!$A$2:$C$241,MATCH(D33,Tabelle2!$C$2:$C$241,0),1)) -> BNDG-X839 | T33: =IF(E33="","",INDEX(Tabelle2!$A$2:$C$241,MATCH(E33,Tabelle2!$C$2:$C$241,0),1)) -> BNDG-A960 | U33: =IF(F33="","",INDEX(Tabelle2!$A$2:$C$241,MATCH(F33,Tabelle2!$C$2:$C$241,0),1)) -> BNDG-D864 | V33: =IF(G33="","",INDEX(Tabelle2!$A$2:$C$241,MATCH(G33,Tabelle2!$C$2:$C$241,0),1)) -> BNDG-B859 | W33: =IF(H33="","",INDEX(Tabelle2!$A$2:$C$241,MATCH(H33,Tabelle2!$C$2:$C$241,0),1)) | X33: =IF(I33="","",INDEX(Tabelle2!$A$2:$C$241,MATCH(I33,Tabelle2!$C$2:$C$241,0),1)) | Y33: =IF(J33="","",INDEX(Tabelle2!$A$2:$C$241,MATCH(J33,Tabelle2!$C$2:$C$241,0),1)) | Z33: =IF(K33="","",INDEX(Tabelle2!$A$2:$C$241,MATCH(K33,Tabelle2!$C$2:$C$241,0),1)) | ... AG33: =IF(R33="","",INDEX(Tabelle2!$A$2:$C$241,MATCH(R33,Tabelle2!$C$2:$C$241,0),1))
A34: 5240 | B34: Dunkelbrauner Ledereinband auf Holzdeckeln, Byzantinische Technik | D34: Fester Einband | E34: Heftung auf versenkte Bünde | F34: Holz (Deckel) | G34: Leder (Bezug) | H34: Bezug vorhanden | I34: Einband byzantinischen Typs | S34: =IF(D34="","",INDEX(Tabelle2!$A$2:$C$241,MATCH(D34,Tabelle2!$C$2:$C$241,0),1)) -> BNDG-A532 | T34: =IF(E34="","",INDEX(Tabelle2!$A$2:$C$241,MATCH(E34,Tabelle2!$C$2:$C$241,0),1)) -> BNDG-B118 | U34: =IF(F34="","",INDEX(Tabelle2!$A$2:$C$241,MATCH(F34,Tabelle2!$C$2:$C$241,0),1)) -> BNDG-D174 | V34: =IF(G34="","",INDEX(Tabelle2!$A$2:$C$241,MATCH(G34,Tabelle2!$C$2:$C$241,0),1)) -> BNDG-E702 | W34: =IF(H34="","",INDEX(Tabelle2!$A$2:$C$241,MATCH(H34,Tabelle2!$C$2:$C$241,0),1)) -> BNDG-F468 | X34: =IF(I34="","",INDEX(Tabelle2!$A$2:$C$241,MATCH(I34,Tabelle2!$C$2:$C$241,0),1)) -> BNDG-X463 | Y34: =IF(J34="","",INDEX(Tabelle2!$A$2:$C$241,MATCH(J34,Tabelle2!$C$2:$C$241,0),1)) | Z34: =IF(K34="","",INDEX(Tabelle2!$A$2:$C$241,MATCH(K34,Tabelle2!$C$2:$C$241,0),1)) | ... AG34: =IF(R34="","",INDEX(Tabelle2!$A$2:$C$241,MATCH(R34,Tabelle2!$C$2:$C$241,0),1))
A35: 5240 | B35: Einband, hell | D35: Einband vorhanden | S35: =IF(D35="","",INDEX(Tabelle2!$A$2:$C$241,MATCH(D35,Tabelle2!$C$2:$C$241,0),1)) -> BNDG-A239 | T35: =IF(E35="","",INDEX(Tabelle2!$A$2:$C$241,MATCH(E35,Tabelle2!$C$2:$C$241,0),1)) | U35: =IF(F35="","",INDEX(Tabelle2!$A$2:$C$241,MATCH(F35,Tabelle2!$C$2:$C$241,0),1)) | V35: =IF(G35="","",INDEX(Tabelle2!$A$2:$C$241,MATCH(G35,Tabelle2!$C$2:$C$241,0),1)) | W35: =IF(H35="","",INDEX(Tabelle2!$A$2:$C$241,MATCH(H35,Tabelle2!$C$2:$C$241,0),1)) | X35: =IF(I35="","",INDEX(Tabelle2!$A$2:$C$241,MATCH(I35,Tabelle2!$C$2:$C$241,0),1)) | Y35: =IF(J35="","",INDEX(Tabelle2!$A$2:$C$241,MATCH(J35,Tabelle2!$C$2:$C$241,0),1)) | Z35: =IF(K35="","",INDEX(Tabelle2!$A$2:$C$241,MATCH(K35,Tabelle2!$C$2:$C$241,0),1)) | ... AG35: =IF(R35="","",INDEX(Tabelle2!$A$2:$C$241,MATCH(R35,Tabelle2!$C$2:$C$241,0),1))
A36: 5240 | B36: Einband, hellbraun | D36: Einband vorhanden | S36: =IF(D36="","",INDEX(Tabelle2!$A$2:$C$241,MATCH(D36,Tabelle2!$C$2:$C$241,0),1)) -> BNDG-A239 | T36: =IF(E36="","",INDEX(Tabelle2!$A$2:$C$241,MATCH(E36,Tabelle2!$C$2:$C$241,0),1)) | U36: =IF(F36="","",INDEX(Tabelle2!$A$2:$C$241,MATCH(F36,Tabelle2!$C$2:$C$241,0),1)) | V36: =IF(G36="","",INDEX(Tabelle2!$A$2:$C$241,MATCH(G36,Tabelle2!$C$2:$C$241,0),1)) | W36: =IF(H36="","",INDEX(Tabelle2!$A$2:$C$241,MATCH(H36,Tabelle2!$C$2:$C$241,0),1)) | X36: =IF(I36="","",INDEX(Tabelle2!$A$2:$C$241,MATCH(I36,Tabelle2!$C$2:$C$241,0),1)) | Y36: =IF(J36="","",INDEX(Tabelle2!$A$2:$C$241,MATCH(J36,Tabelle2!$C$2:$C$241,0),1)) | Z36: =IF(K36="","",INDEX(Tabelle2!$A$2:$C$241,MATCH(K36,Tabelle2!$C$2:$C$241,0),1)) | ... AG36: =IF(R36="","",INDEX(Tabelle2!$A$2:$C$241,MATCH(R36,Tabelle2!$C$2:$C$241,0),1))
A37: 5240 | B37: Einband, modern | D37: Einband vorhanden | S37: =IF(D37="","",INDEX(Tabelle2!$A$2:$C$241,MATCH(D37,Tabelle2!$C$2:$C$241,0),1)) -> BNDG-A239 | T37: =IF(E37="","",INDEX(Tabelle2!$A$2:$C$241,MATCH(E37,Tabelle2!$C$2:$C$241,0),1)) | U37: =IF(F37="","",INDEX(Tabelle2!$A$2:$C$241,MATCH(F37,Tabelle2!$C$2:$C$241,0),1)) | V37: =IF(G37="","",INDEX(Tabelle2!$A$2:$C$241,MATCH(G37,Tabelle2!$C$2:$C$241,0),1)) | W37: =IF(H37="","",INDEX(Tabelle2!$A$2:$C$241,MATCH(H37,Tabelle2!$C$2:$C$241,0),1)) | X37: =IF(I37="","",INDEX(Tabelle2!$A$2:$C$241,MATCH(I37,Tabelle2!$C$2:$C$241,0),1)) | Y37: =IF(J37="","",INDEX(Tabelle2!$A$2:$C$241,MATCH(J37,Tabelle2!$C$2:$C$241,0),1)) | Z37: =IF(K37="","",INDEX(Tabelle2!$A$2:$C$241,MATCH(K37,Tabelle2!$C$2:$C$241,0),1)) | ... AG37: =IF(R37="","",INDEX(Tabelle2!$A$2:$C$241,MATCH(R37,Tabelle2!$C$2:$C$241,0),1))
A38: 5240 | B38: Einband, ottonisch | D38: Einband vorhanden | S38: =IF(D38="","",INDEX(Tabelle2!$A$2:$C$241,MATCH(D38,Tabelle2!$C$2:$C$241,0),1)) -> BNDG-A239 | T38: =IF(E38="","",INDEX(Tabelle2!$A$2:$C$241,MATCH(E38,Tabelle2!$C$2:$C$241,0),1)) | U38: =IF(F38="","",INDEX(Tabelle2!$A$2:$C$241,MATCH(F38,Tabelle2!$C$2:$C$241,0),1)) | V38: =IF(G38="","",INDEX(Tabelle2!$A$2:$C$241,MATCH(G38,Tabelle2!$C$2:$C$241,0),1)) | W38: =IF(H38="","",INDEX(Tabelle2!$A$2:$C$241,MATCH(H38,Tabelle2!$C$2:$C$241,0),1)) | X38: =IF(I38="","",INDEX(Tabelle2!$A$2:$C$241,MATCH(I38,Tabelle2!$C$2:$C$241,0),1)) | Y38: =IF(J38="","",INDEX(Tabelle2!$A$2:$C$241,MATCH(J38,Tabelle2!$C$2:$C$241,0),1)) | Z38: =IF(K38="","",INDEX(Tabelle2!$A$2:$C$241,MATCH(K38,Tabelle2!$C$2:$C$241,0),1)) | ... AG38: =IF(R38="","",INDEX(Tabelle2!$A$2:$C$241,MATCH(R38,Tabelle2!$C$2:$C$241,0),1))
A39: 5240 | B39: Einband, spätgotisch | D39: Einband vorhanden | S39: =IF(D39="","",INDEX(Tabelle2!$A$2:$C$241,MATCH(D39,Tabelle2!$C$2:$C$241,0),1)) -> BNDG-A239 | T39: =IF(E39="","",INDEX(Tabelle2!$A$2:$C$241,MATCH(E39,Tabelle2!$C$2:$C$241,0),1)) | U39: =IF(F39="","",INDEX(Tabelle2!$A$2:$C$241,MATCH(F39,Tabelle2!$C$2:$C$241,0),1)) | V39: =IF(G39="","",INDEX(Tabelle2!$A$2:$C$241,MATCH(G39,Tabelle2!$C$2:$C$241,0),1)) | W39: =IF(H39="","",INDEX(Tabelle2!$A$2:$C$241,MATCH(H39,Tabelle2!$C$2:$C$241,0),1)) | X39: =IF(I39="","",INDEX(Tabelle2!$A$2:$C$241,MATCH(I39,Tabelle2!$C$2:$C$241,0),1)) | Y39: =IF(J39="","",INDEX(Tabelle2!$A$2:$C$241,MATCH(J39,Tabelle2!$C$2:$C$241,0),1)) | Z39: =IF(K39="","",INDEX(Tabelle2!$A$2:$C$241,MATCH(K39,Tabelle2!$C$2:$C$241,0),1)) | ... AG39: =IF(R39="","",INDEX(Tabelle2!$A$2:$C$241,MATCH(R39,Tabelle2!$C$2:$C$241,0),1))
A40: 5240 | B40: Einband, spätgotischer | D40: Einband vorhanden | S40: =IF(D40="","",INDEX(Tabelle2!$A$2:$C$241,MATCH(D40,Tabelle2!$C$2:$C$241,0),1)) -> BNDG-A239 | T40: =IF(E40="","",INDEX(Tabelle2!$A$2:$C$241,MATCH(E40,Tabelle2!$C$2:$C$241,0),1)) | U40: =IF(F40="","",INDEX(Tabelle2!$A$2:$C$241,MATCH(F40,Tabelle2!$C$2:$C$241,0),1)) | V40: =IF(G40="","",INDEX(Tabelle2!$A$2:$C$241,MATCH(G40,Tabelle2!$C$2:$C$241,0),1)) | W40: =IF(H40="","",INDEX(Tabelle2!$A$2:$C$241,MATCH(H40,Tabelle2!$C$2:$C$241,0),1)) | X40: =IF(I40="","",INDEX(Tabelle2!$A$2:$C$241,MATCH(I40,Tabelle2!$C$2:$C$241,0),1)) | Y40: =IF(J40="","",INDEX(Tabelle2!$A$2:$C$241,MATCH(J40,Tabelle2!$C$2:$C$241,0),1)) | Z40: =IF(K40="","",INDEX(Tabelle2!$A$2:$C$241,MATCH(K40,Tabelle2!$C$2:$C$241,0),1)) | ... AG40: =IF(R40="","",INDEX(Tabelle2!$A$2:$C$241,MATCH(R40,Tabelle2!$C$2:$C$241,0),1))
...

Sheet Tabelle2
A1: Notation | B1: UUID | C1: Label | D1: Label_en
A2: BNDG-A180 | B2: NORM-821ba04d-895d-3e45-970b-3a93d5a7ab7f | C2: Einband entfernt (mit Resten eines ursprünglichen Einbands) | D2: binding removed
A3: BNDG-A206 | B3: NORM-2ce4fc63-ba6e-3026-a440-62a4b8e9642f | C3: Fester Einband ohne Klappe | D3: binding without flap
A4: BNDG-A239 | B4: NORM-f3bd05cd-c31d-314b-bafa-cda21482d0c0 | C4: Einband vorhanden | D4: with binding
A5: BNDG-A284 | B5: NORM-e2f86653-17df-3aa8-98e6-19722454124c | C5: Einband ursprünglich nicht vorhanden | D5: originally without binding
A6: BNDG-A343 | B6: NORM-bdf90ca7-680c-3791-83c6-13ded902bd33 | C6: Loser Umschlag | D6: wrapper
A7: BNDG-A345 | B7: NORM-02dc5af4-364a-37b1-a035-aa54168f14c4 | C7: Fester Einband mit Klappe | D7: binding with flap
A8: BNDG-A415 | B8: NORM-c47f976e-aba5-36ad-8a0e-d962b14d01e8 | C8: Flexibler Einband ohne Klappe | D8: limp binding without flap
A9: BNDG-A460 | B9: NORM-1727e64f-d87c-34a8-a07c-ae1d6d569d71 | C9: Einband nicht vorhanden | D9: without binding
A10: BNDG-A507 | B10: NORM-75d4cbe0-0e1f-3ed4-a01a-dc3bdf56493c | C10: Flexibler Einband | D10: limp binding
A11: BNDG-A532 | B11: NORM-ac703c4f-45c9-3940-9def-d71b8e5b5fc3 | C11: Fester Einband | D11: hardbound
A12: BNDG-A960 | B12: NORM-42f87478-1152-339d-8093-f78a56dc1e82 | C12: Flexibler Einband mit Klappe | D12: limp binding with flap
... A241: BNDG-X990 | B241: NORM-ca4cd5ac-19e8-30f3-bd9c-2e182b57a8f7 | C241: Kalbsledereinband | D241: calfskin binding
