Workbook

Sheet Tabelle1
A1: Indexfeld | B1: Begriff im Indexfeld | C1: Anzahl Vorkommnisse | D1: Zugewiesener Thesaurus-/Fachbegriff | E1: Zugewiesener Thesaurus-/Fachbegriff | F1: Zugewiesener Thesaurus-/Fachbegriff | G1: Zugewiesener Thesaurus-/Fachbegriff | H1: Zugewiesener Thesaurus-/Fachbegriff | I1: Zugewiesener Thesaurus-/Fachbegriff | J1: Zugewiesener Thesaurus-/Fachbegriff | K1: Zugewiesener Thesaurus-/Fachbegriff | L1: Zugewiesener Thesaurus-/Fachbegriff | M1: Zugewiesener Thesaurus-/Fachbegriff | N1: Zugewiesener Thesaurus-/Fachbegriff | O1: Zugewiesener Thesaurus-/Fachbegriff | P1: Zugewiesener Thesaurus-/Fachbegriff | Q1: Zugewiesener Thesaurus-/Fachbegriff | R1: Zugewiesener Thesaurus-/Fachbegriff | S1: Notation | T1: Notation | U1: Notation | V1: Notation | W1: Notation | X1: Notation | Y1: Notation | Z1: Notation | AA1: Notation | AB1: Notation | AC1: Notation | AD1: Notation | AE1: Notation | AF1: Notation | AG1: Notation
A2: 5710 | B2: Helmst. 389 ist sehr wahrscheinlich ein westfälischer Text, eventuell aus dem Grenzgebiet mit dem Nordniederdeutschen (Langbroek, Die Sprache [siehe unten], 209). | D2: Westfälisch | E2: Nordniederdeutsch | T2: =IF(D2="","",INDEX(Tabelle2!$A$2:$B$74,MATCH(D2,Tabelle2!$B$2:$B$74,0),1)) -> WRLA-A100 | U2: =IF(E2="","",INDEX(Tabelle2!$A$2:$B$74,MATCH(E2,Tabelle2!$B$2:$B$74,0),1)) -> WRLA-A496 | V2: =IF(F2="","",INDEX(Tabelle2!$A$2:$B$74,MATCH(F2,Tabelle2!$B$2:$B$74,0),1)) | W2: =IF(G2="","",INDEX(Tabelle2!$A$2:$B$74,MATCH(G2,Tabelle2!$B$2:$B$74,0),1))
A3: 5710 | B3: (nord?)bairisch | D3: Bairisch | T3: =IF(D3="","",INDEX(Tabelle2!$A$2:$B$74,MATCH(D3,Tabelle2!$B$2:$B$74,0),1)) -> WRLA-A523 | U3: =IF(E3="","",INDEX(Tabelle2!$A$2:$B$74,MATCH(E3,Tabelle2!$B$2:$B$74,0),1)) | V3: =IF(F3="","",INDEX(Tabelle2!$A$2:$B$74,MATCH(F3,Tabelle2!$B$2:$B$74,0),1)) | W3: =IF(G3="","",INDEX(Tabelle2!$A$2:$B$74,MATCH(G3,Tabelle2!$B$2:$B$74,0),1))
A4: 5710 | B4: (ost)mitteldeutsch mit einigen bairischen Schreibeigentümlichkeiten. | D4: Ostmitteldeutsch | E4: Bairisch | T4: =IF(D4="","",INDEX(Tabelle2!$A$2:$B$74,MATCH(D4,Tabelle2!$B$2:$B$74,0),1)) -> WRLA-A659 | U4: =IF(E4="","",INDEX(Tabelle2!$A$2:$B$74,MATCH(E4,Tabelle2!$B$2:$B$74,0),1)) -> WRLA-A523 | V4: =IF(F4="","",INDEX(Tabelle2!$A$2:$B$74,MATCH(F4,Tabelle2!$B$2:$B$74,0),1)) | W4: =IF(G4="","",INDEX(Tabelle2!$A$2:$B$74,MATCH(G4,Tabelle2!$B$2:$B$74,0),1)) | AB4: =IF(M4="","",INDEX(Tabelle2!$A$2:$B$239,MATCH(M4,Tabelle2!$B$2:$B$239,0),1)) | AC4: =IF(N4="","",INDEX(Tabelle2!$A$2:$B$239,MATCH(N4,Tabelle2!$B$2:$B$239,0),1)) | AD4: =IF(O4="","",INDEX(Tabelle2!$A$2:$B$239,MATCH(O4,Tabelle2!$B$2:$B$239,0),1)) | AE4: =IF(P4="","",INDEX(Tabelle2!$A$2:$B$239,MATCH(P4,Tabelle2!$B$2:$B$239,0),1)) | AF4: =IF(Q4="","",INDEX(Tabelle2!$A$2:$B$239,MATCH(Q4,Tabelle2!$B$2:$B$239,0),1)) | AG4: =IF(R4="","",INDEX(Tabelle2!$A$2:$B$239,MATCH(R4,Tabelle2!$B$2:$B$239,0),1))
A5: 5710 | B5: (ost)oberdeutsch mit wenigen mitteldeutschen Formen. | D5: Bairisch | E5: Mitteldeutsch | T5: =IF(D5="","",INDEX(Tabelle2!$A$2:$B$74,MATCH(D5,Tabelle2!$B$2:$B$74,0),1)) -> WRLA-A523 | U5: =IF(E5="","",INDEX(Tabelle2!$A$2:$B$74,MATCH(E5,Tabelle2!$B$2:$B$74,0),1)) -> WRLA-A129 | V5: =IF(F5="","",INDEX(Tabelle2!$A$2:$B$74,MATCH(F5,Tabelle2!$B$2:$B$74,0),1)) | W5: =IF(G5="","",INDEX(Tabelle2!$A$2:$B$74,MATCH(G5,Tabelle2!$B$2:$B$74,0),1))
A6: 5710 | B6: alemanisch | D6: Alemannisch | T6: =IF(D6="","",INDEX(Tabelle2!$A$2:$B$74,MATCH(D6,Tabelle2!$B$2:$B$74,0),1)) -> WRLA-A317 | U6: =IF(E6="","",INDEX(Tabelle2!$A$2:$B$74,MATCH(E6,Tabelle2!$B$2:$B$74,0),1)) | V6: =IF(F6="","",INDEX(Tabelle2!$A$2:$B$74,MATCH(F6,Tabelle2!$B$2:$B$74,0),1)) | W6: =IF(G6="","",INDEX(Tabelle2!$A$2:$B$74,MATCH(G6,Tabelle2!$B$2:$B$74,0),1))
A7: 5710 | B7: alemannisch | D7: Alemannisch | T7: =IF(D7="","",INDEX(Tabelle2!$A$2:$B$74,MATCH(D7,Tabelle2!$B$2:$B$74,0),1)) -> WRLA-A317 | U7: =IF(E7="","",INDEX(Tabelle2!$A$2:$B$74,MATCH(E7,Tabelle2!$B$2:$B$74,0),1)) | V7: =IF(F7="","",INDEX(Tabelle2!$A$2:$B$74,MATCH(F7,Tabelle2!$B$2:$B$74,0),1)) | W7: =IF(G7="","",INDEX(Tabelle2!$A$2:$B$74,MATCH(G7,Tabelle2!$B$2:$B$74,0),1))
A8: 5710 | B8: alemannisch, Rezepte teilweise mit mitteldeutschen Formen. | D8: Alemannisch | E8: Mitteldeutsch | T8: =IF(D8="","",INDEX(Tabelle2!$A$2:$B$74,MATCH(D8,Tabelle2!$B$2:$B$74,0),1)) -> WRLA-A317 | U8: =IF(E8="","",INDEX(Tabelle2!$A$2:$B$74,MATCH(E8,Tabelle2!$B$2:$B$74,0),1)) -> WRLA-A129 | V8: =IF(F8="","",INDEX(Tabelle2!$A$2:$B$74,MATCH(F8,Tabelle2!$B$2:$B$74,0),1)) | W8: =IF(G8="","",INDEX(Tabelle2!$A$2:$B$74,MATCH(G8,Tabelle2!$B$2:$B$74,0),1))
A9: 5710 | B9: alemannisch? | D9: Alemannisch | T9: =IF(D9="","",INDEX(Tabelle2!$A$2:$B$74,MATCH(D9,Tabelle2!$B$2:$B$74,0),1)) -> WRLA-A317 | U9: =IF(E9="","",INDEX(Tabelle2!$A$2:$B$74,MATCH(E9,Tabelle2!$B$2:$B$74,0),1)) | V9: =IF(F9="","",INDEX(Tabelle2!$A$2:$B$74,MATCH(F9,Tabelle2!$B$2:$B$74,0),1)) | W9: =IF(G9="","",INDEX(Tabelle2!$A$2:$B$74,MATCH(G9,Tabelle2!$B$2:$B$74,0),1))
A10: 5710 | B10: alemannisch? / | D10: Alemannisch | T10: =IF(D10="","",INDEX(Tabelle2!$A$2:$B$74,MATCH(D10,Tabelle2!$B$2:$B$74,0),1)) -> WRLA-A317 | U10: =IF(E10="","",INDEX(Tabelle2!$A$2:$B$74,MATCH(E10,Tabelle2!$B$2:$B$74,0),1)) | V10: =IF(F10="","",INDEX(Tabelle2!$A$2:$B$74,MATCH(F10,Tabelle2!$B$2:$B$74,0),1)) | W10: =IF(G10="","",INDEX(Tabelle2!$A$2:$B$74,MATCH(G10,Tabelle2!$B$2:$B$74,0),1))
A11: 5710 | B11: alemannisch / | D11: Alemannisch | T11: =IF(D11="","",INDEX(Tabelle2!$A$2:$B$74,MATCH(D11,Tabelle2!$B$2:$B$74,0),1)) -> WRLA-A317 | U11: =IF(E11="","",INDEX(Tabelle2!$A$2:$B$74,MATCH(E11,Tabelle2!$B$2:$B$74,0),1)) | V11: =IF(F11="","",INDEX(Tabelle2!$A$2:$B$74,MATCH(F11,Tabelle2!$B$2:$B$74,0),1)) | W11: =IF(G11="","",INDEX(Tabelle2!$A$2:$B$74,MATCH(G11,Tabelle2!$B$2:$B$74,0),1))
A12: 5710 | B12: alemannisch/schwäbisch | D12: Alemannisch | E12: Schwäbisch | T12: =IF(D12="","",INDEX(Tabelle2!$A$2:$B$74,MATCH(D12,Tabelle2!$B$2:$B$74,0),1)) -> WRLA-A317 | U12: =IF(E12="","",INDEX(Tabelle2!$A$2:$B$74,MATCH(E12,Tabelle2!$B$2:$B$74,0),1)) -> WRLA-A273 | V12: =IF(F12="","",INDEX(Tabelle2!$A$2:$B$74,MATCH(F12,Tabelle2!$B$2:$B$74,0),1)) | W12: =IF(G12="","",INDEX(Tabelle2!$A$2:$B$74,MATCH(G12,Tabelle2!$B$2:$B$74,0),1))
A13: 5710 | B13: alemannisch. | D13: Alemannisch | T13: =IF(D13="","",INDEX(Tabelle2!$A$2:$B$74,MATCH(D13,Tabelle2!$B$2:$B$74,0),1)) -> WRLA-A317 | U13: =IF(E13="","",INDEX(Tabelle2!$A$2:$B$74,MATCH(E13,Tabelle2!$B$2:$B$74,0),1)) | V13: =IF(F13="","",INDEX(Tabelle2!$A$2:$B$74,MATCH(F13,Tabelle2!$B$2:$B$74,0),1)) | W13: =IF(G13="","",INDEX(Tabelle2!$A$2:$B$74,MATCH(G13,Tabelle2!$B$2:$B$74,0),1))
A14: 5710 | B14: alemannisch ((317recto/verso) | D14: Alemannisch | T14: =IF(D14="","",INDEX(Tabelle2!$A$2:$B$74,MATCH(D14,Tabelle2!$B$2:$B$74,0),1)) -> WRLA-A317 | U14: =IF(E14="","",INDEX(Tabelle2!$A$2:$B$74,MATCH(E14,Tabelle2!$B$2:$B$74,0),1)) | V14: =IF(F14="","",INDEX(Tabelle2!$A$2:$B$74,MATCH(F14,Tabelle2!$B$2:$B$74,0),1)) | W14: =IF(G14="","",INDEX(Tabelle2!$A$2:$B$74,MATCH(G14,Tabelle2!$B$2:$B$74,0),1))
A15: 5710 | B15: alemannisch (28verso-42recto) | D15: Alemannisch | T15: =IF(D15="","",INDEX(Tabelle2!$A$2:$B$74,MATCH(D15,Tabelle2!$B$2:$B$74,0),1)) -> WRLA-A317 | U15: =IF(E15="","",INDEX(Tabelle2!$A$2:$B$74,MATCH(E15,Tabelle2!$B$2:$B$74,0),1)) | V15: =IF(F15="","",INDEX(Tabelle2!$A$2:$B$74,MATCH(F15,Tabelle2!$B$2:$B$74,0),1)) | W15: =IF(G15="","",INDEX(Tabelle2!$A$2:$B$74,MATCH(G15,Tabelle2!$B$2:$B$74,0),1))
A16: 5710 | B16: alemannisch-bairisch | D16: Alemannisch | E16: Bairisch | T16: =IF(D16="","",INDEX(Tabelle2!$A$2:$B$74,MATCH(D16,Tabelle2!$B$2:$B$74,0),1)) -> WRLA-A317 | U16: =IF(E16="","",INDEX(Tabelle2!$A$2:$B$74,MATCH(E16,Tabelle2!$B$2:$B$74,0),1)) -> WRLA-A523 | V16: =IF(F16="","",INDEX(Tabelle2!$A$2:$B$74,MATCH(F16,Tabelle2!$B$2:$B$74,0),1)) | W16: =IF(G16="","",INDEX(Tabelle2!$A$2:$B$74,MATCH(G16,Tabelle2!$B$2:$B$74,0),1))
A17: 5710 | B17: alemannische | D17: Alemannisch | T17: =IF(D17="","",INDEX(Tabelle2!$A$2:$B$74,MATCH(D17,Tabelle2!$B$2:$B$74,0),1)) -> WRLA-A317 | U17: =IF(E17="","",INDEX(Tabelle2!$A$2:$B$74,MATCH(E17,Tabelle2!$B$2:$B$74,0),1)) | V17: =IF(F17="","",INDEX(Tabelle2!$A$2:$B$74,MATCH(F17,Tabelle2!$B$2:$B$74,0),1)) | W17: =IF(G17="","",INDEX(Tabelle2!$A$2:$B$74,MATCH(G17,Tabelle2!$B$2:$B$74,0),1))
A18: 5710 | B18: alemannisch-elsässisch | D18: Alemannisch | E18: Elsässisch | T18: =IF(D18="","",INDEX(Tabelle2!$A$2:$B$74,MATCH(D18,Tabelle2!$B$2:$B$74,0),1)) -> WRLA-A317 | U18: =IF(E18="","",INDEX(Tabelle2!$A$2:$B$74,MATCH(E18,Tabelle2!$B$2:$B$74,0),1)) -> WRLA-A326 | V18: =IF(F18="","",INDEX(Tabelle2!$A$2:$B$74,MATCH(F18,Tabelle2!$B$2:$B$74,0),1)) | W18: =IF(G18="","",INDEX(Tabelle2!$A$2:$B$74,MATCH(G18,Tabelle2!$B$2:$B$74,0),1))
A19: 5710 | B19: alemannisch-fränkisch | D19: Alemannisch | E19: Nordoberdeutsch | T19: =IF(D19="","",INDEX(Tabelle2!$A$2:$B$74,MATCH(D19,Tabelle2!$B$2:$B$74,0),1)) -> WRLA-A317 | U19: =IF(E19="","",INDEX(Tabelle2!$A$2:$B$74,MATCH(E19,Tabelle2!$B$2:$B$74,0),1)) -> WRLA-A551 | V19: =IF(F19="","",INDEX(Tabelle2!$A$2:$B$74,MATCH(F19,Tabelle2!$B$2:$B$74,0),1)) | W19: =IF(G19="","",INDEX(Tabelle2!$A$2:$B$74,MATCH(G19,Tabelle2!$B$2:$B$74,0),1))
A20: 5710 | B20: alemannisch mit schwäbischen Formen | D20: Alemannisch | E20: Schwäbisch | T20: =IF(D20="","",INDEX(Tabelle2!$A$2:$B$74,MATCH(D20,Tabelle2!$B$2:$B$74,0),1)) -> WRLA-A317 | U20: =IF(E20="","",INDEX(Tabelle2!$A$2:$B$74,MATCH(E20,Tabelle2!$B$2:$B$74,0),1)) -> WRLA-A273 | V20: =IF(F20="","",INDEX(Tabelle2!$A$2:$B$74,MATCH(F20,Tabelle2!$B$2:$B$74,0),1)) | W20: =IF(G20="","",INDEX(Tabelle2!$A$2:$B$74,MATCH(G20,Tabelle2!$B$2:$B$74,0),1))
A21: 5710 | B21: alemannisch mit schwäbischen Formen und Schreibeigentümlichkeiten. | D21: Alemannisch | E21: Schwäbisch | T21: =IF(D21="","",INDEX(Tabelle2!$A$2:$B$74,MATCH(D21,Tabelle2!$B$2:$B$74,0),1)) -> WRLA-A317 | U21: =IF(E21="","",INDEX(Tabelle2!$A$2:$B$74,MATCH(E21,Tabelle2!$B$2:$B$74,0),1)) -> WRLA-A273 | V21: =IF(F21="","",INDEX(Tabelle2!$A$2:$B$74,MATCH(F21,Tabelle2!$B$2:$B$74,0),1)) | W21: =IF(G21="","",INDEX(Tabelle2!$A$2:$B$74,MATCH(G21,Tabelle2!$B$2:$B$74,0),1))
A22: 5710 | B22: alemannisch-schwäbisch | D22: Alemannisch | E22: Schwäbisch | T22: =IF(D22="","",INDEX(Tabelle2!$A$2:$B$74,MATCH(D22,Tabelle2!$B$2:$B$74,0),1)) -> WRLA-A317 | U22: =IF(E22="","",INDEX(Tabelle2!$A$2:$B$74,MATCH(E22,Tabelle2!$B$2:$B$74,0),1)) -> WRLA-A273 | V22: =IF(F22="","",INDEX(Tabelle2!$A$2:$B$74,MATCH(F22,Tabelle2!$B$2:$B$74,0),1)) | W22: =IF(G22="","",INDEX(Tabelle2!$A$2:$B$74,MATCH(G22,Tabelle2!$B$2:$B$74,0),1))
A23: 5710 | B23: bairisch | D23: Bairisch | T23: =IF(D23="","",INDEX(Tabelle2!$A$2:$B$74,MATCH(D23,Tabelle2!$B$2:$B$74,0),1)) -> WRLA-A523 | U23: =IF(E23="","",INDEX(Tabelle2!$A$2:$B$74,MATCH(E23,Tabelle2!$B$2:$B$74,0),1)) | V23: =IF(F23="","",INDEX(Tabelle2!$A$2:$B$74,MATCH(F23,Tabelle2!$B$2:$B$74,0),1)) | W23: =IF(G23="","",INDEX(Tabelle2!$A$2:$B$74,MATCH(G23,Tabelle2!$B$2:$B$74,0),1))
A24: 5710 | B24: Bairisch | D24: Bairisch | T24: =IF(D24="","",INDEX(Tabelle2!$A$2:$B$74,MATCH(D24,Tabelle2!$B$2:$B$74,0),1)) -> WRLA-A523 | U24: =IF(E24="","",INDEX(Tabelle2!$A$2:$B$74,MATCH(E24,Tabelle2!$B$2:$B$74,0),1)) | V24: =IF(F24="","",INDEX(Tabelle2!$A$2:$B$74,MATCH(F24,Tabelle2!$B$2:$B$74,0),1)) | W24: =IF(G24="","",INDEX(Tabelle2!$A$2:$B$74,MATCH(G24,Tabelle2!$B$2:$B$74,0),1))
A25: 5710 | B25: bairisch? | D25: Bairisch | T25: =IF(D25="","",INDEX(Tabelle2!$A$2:$B$74,MATCH(D25,Tabelle2!$B$2:$B$74,0),1)) -> WRLA-A523 | U25: =IF(E25="","",INDEX(Tabelle2!$A$2:$B$74,MATCH(E25,Tabelle2!$B$2:$B$74,0),1)) | V25: =IF(F25="","",INDEX(Tabelle2!$A$2:$B$74,MATCH(F25,Tabelle2!$B$2:$B$74,0),1)) | W25: =IF(G25="","",INDEX(Tabelle2!$A$2:$B$74,MATCH(G25,Tabelle2!$B$2:$B$74,0),1))
A26: 5710 | B26: bairisch? (althochdeutsch) | D26: Bairisch | T26: =IF(D26="","",INDEX(Tabelle2!$A$2:$B$74,MATCH(D26,Tabelle2!$B$2:$B$74,0),1)) -> WRLA-A523 | U26: =IF(E26="","",INDEX(Tabelle2!$A$2:$B$74,MATCH(E26,Tabelle2!$B$2:$B$74,0),1)) | V26: =IF(F26="","",INDEX(Tabelle2!$A$2:$B$74,MATCH(F26,Tabelle2!$B$2:$B$74,0),1)) | W26: =IF(G26="","",INDEX(Tabelle2!$A$2:$B$74,MATCH(G26,Tabelle2!$B$2:$B$74,0),1))
A27: 5710 | B27: bairisch / | D27: Bairisch | T27: =IF(D27="","",INDEX(Tabelle2!$A$2:$B$74,MATCH(D27,Tabelle2!$B$2:$B$74,0),1)) -> WRLA-A523 | U27: =IF(E27="","",INDEX(Tabelle2!$A$2:$B$74,MATCH(E27,Tabelle2!$B$2:$B$74,0),1)) | V27: =IF(F27="","",INDEX(Tabelle2!$A$2:$B$74,MATCH(F27,Tabelle2!$B$2:$B$74,0),1)) | W27: =IF(G27="","",INDEX(Tabelle2!$A$2:$B$74,MATCH(G27,Tabelle2!$B$2:$B$74,0),1))
A28: 5710 | B28: bairisch (Hand I) | D28: Bairisch | T28: =IF(D28="","",INDEX(Tabelle2!$A$2:$B$74,MATCH(D28,Tabelle2!$B$2:$B$74,0),1)) -> WRLA-A523 | U28: =IF(E28="","",INDEX(Tabelle2!$A$2:$B$74,MATCH(E28,Tabelle2!$B$2:$B$74,0),1)) | V28: =IF(F28="","",INDEX(Tabelle2!$A$2:$B$74,MATCH(F28,Tabelle2!$B$2:$B$74,0),1)) | W28: =IF(G28="","",INDEX(Tabelle2!$A$2:$B$74,MATCH(G28,Tabelle2!$B$2:$B$74,0),1))
A29: 5710 | B29: bairisch (Hand II-IV) | D29: Bairisch | T29: =IF(D29="","",INDEX(Tabelle2!$A$2:$B$74,MATCH(D29,Tabelle2!$B$2:$B$74,0),1)) -> WRLA-A523 | U29: =IF(E29="","",INDEX(Tabelle2!$A$2:$B$74,MATCH(E29,Tabelle2!$B$2:$B$74,0),1)) | V29: =IF(F29="","",INDEX(Tabelle2!$A$2:$B$74,MATCH(F29,Tabelle2!$B$2:$B$74,0),1)) | W29: =IF(G29="","",INDEX(Tabelle2!$A$2:$B$74,MATCH(G29,Tabelle2!$B$2:$B$74,0),1))
A30: 5710 | B30: bairisch (III.a.-b.), hochdeutsch mit wenigen spezifisch bairischen Formen (III.c.). | D30: Bairisch | T30: =IF(D30="","",INDEX(Tabelle2!$A$2:$B$74,MATCH(D30,Tabelle2!$B$2:$B$74,0),1)) -> WRLA-A523 | U30: =IF(E30="","",INDEX(Tabelle2!$A$2:$B$74,MATCH(E30,Tabelle2!$B$2:$B$74,0),1)) | V30: =IF(F30="","",INDEX(Tabelle2!$A$2:$B$74,MATCH(F30,Tabelle2!$B$2:$B$74,0),1)) | W30: =IF(G30="","",INDEX(Tabelle2!$A$2:$B$74,MATCH(G30,Tabelle2!$B$2:$B$74,0),1))
A31: 5710 | B31: bairisch (Vorlage?) mit wenigen ostfränkischen Formen (113rectoa-151rectob) | D31: Bairisch | E31: Ostfränkisch | T31: =IF(D31="","",INDEX(Tabelle2!$A$2:$B$74,MATCH(D31,Tabelle2!$B$2:$B$74,0),1)) -> WRLA-A523 | U31: =IF(E31="","",INDEX(Tabelle2!$A$2:$B$74,MATCH(E31,Tabelle2!$B$2:$B$74,0),1)) -> WRLA-A139 | V31: =IF(F31="","",INDEX(Tabelle2!$A$2:$B$74,MATCH(F31,Tabelle2!$B$2:$B$74,0),1)) | W31: =IF(G31="","",INDEX(Tabelle2!$A$2:$B$74,MATCH(G31,Tabelle2!$B$2:$B$74,0),1))
A32: 5710 | B32: bairische Mundart | D32: Bairisch | T32: =IF(D32="","",INDEX(Tabelle2!$A$2:$B$74,MATCH(D32,Tabelle2!$B$2:$B$74,0),1)) -> WRLA-A523 | U32: =IF(E32="","",INDEX(Tabelle2!$A$2:$B$74,MATCH(E32,Tabelle2!$B$2:$B$74,0),1)) | V32: =IF(F32="","",INDEX(Tabelle2!$A$2:$B$74,MATCH(F32,Tabelle2!$B$2:$B$74,0),1)) | W32: =IF(G32="","",INDEX(Tabelle2!$A$2:$B$74,MATCH(G32,Tabelle2!$B$2:$B$74,0),1))
A33: 5710 | B33: bairischen Schreibeigentümlichkeiten | D33: Bairisch | T33: =IF(D33="","",INDEX(Tabelle2!$A$2:$B$74,MATCH(D33,Tabelle2!$B$2:$B$74,0),1)) -> WRLA-A523 | U33: =IF(E33="","",INDEX(Tabelle2!$A$2:$B$74,MATCH(E33,Tabelle2!$B$2:$B$74,0),1)) | V33: =IF(F33="","",INDEX(Tabelle2!$A$2:$B$74,MATCH(F33,Tabelle2!$B$2:$B$74,0),1)) | W33: =IF(G33="","",INDEX(Tabelle2!$A$2:$B$74,MATCH(G33,Tabelle2!$B$2:$B$74,0),1))
A34: 5710 | B34: bairisch mit fränkischen Elementen | D34: Bairisch | E34: Nordoberdeutsch | T34: =IF(D34="","",INDEX(Tabelle2!$A$2:$B$74,MATCH(D34,Tabelle2!$B$2:$B$74,0),1)) -> WRLA-A523 | U34: =IF(E34="","",INDEX(Tabelle2!$A$2:$B$74,MATCH(E34,Tabelle2!$B$2:$B$74,0),1)) -> WRLA-A551 | V34: =IF(F34="","",INDEX(Tabelle2!$A$2:$B$74,MATCH(F34,Tabelle2!$B$2:$B$74,0),1)) | W34: =IF(G34="","",INDEX(Tabelle2!$A$2:$B$74,MATCH(G34,Tabelle2!$B$2:$B$74,0),1))
A35: 5710 | B35: bairisch mit mitteldeutschen Einflüssen | D35: Bairisch | E35: Mitteldeutsch | T35: =IF(D35="","",INDEX(Tabelle2!$A$2:$B$74,MATCH(D35,Tabelle2!$B$2:$B$74,0),1)) -> WRLA-A523 | U35: =IF(E35="","",INDEX(Tabelle2!$A$2:$B$74,MATCH(E35,Tabelle2!$B$2:$B$74,0),1)) -> WRLA-A129 | V35: =IF(F35="","",INDEX(Tabelle2!$A$2:$B$74,MATCH(F35,Tabelle2!$B$2:$B$74,0),1)) | W35: =IF(G35="","",INDEX(Tabelle2!$A$2:$B$74,MATCH(G35,Tabelle2!$B$2:$B$74,0),1))
A36: 5710 | B36: bairisch mit mitteldeutschen Formen | D36: Bairisch | E36: Mitteldeutsch | T36: =IF(D36="","",INDEX(Tabelle2!$A$2:$B$74,MATCH(D36,Tabelle2!$B$2:$B$74,0),1)) -> WRLA-A523 | U36: =IF(E36="","",INDEX(Tabelle2!$A$2:$B$74,MATCH(E36,Tabelle2!$B$2:$B$74,0),1)) -> WRLA-A129 | V36: =IF(F36="","",INDEX(Tabelle2!$A$2:$B$74,MATCH(F36,Tabelle2!$B$2:$B$74,0),1)) | W36: =IF(G36="","",INDEX(Tabelle2!$A$2:$B$74,MATCH(G36,Tabelle2!$B$2:$B$74,0),1))
A37: 5710 | B37: bairisch mit mitteldeutschen und wenigen alemannischen und schwäbischen Formen | D37: Bairisch | E37: Mitteldeutsch | F37: Alemannisch | G37: Schwäbisch | T37: =IF(D37="","",INDEX(Tabelle2!$A$2:$B$74,MATCH(D37,Tabelle2!$B$2:$B$74,0),1)) -> WRLA-A523 | U37: =IF(E37="","",INDEX(Tabelle2!$A$2:$B$74,MATCH(E37,Tabelle2!$B$2:$B$74,0),1)) -> WRLA-A129 | V37: =IF(F37="","",INDEX(Tabelle2!$A$2:$B$74,MATCH(F37,Tabelle2!$B$2:$B$74,0),1)) -> WRLA-A317 | W37: =IF(G37="","",INDEX(Tabelle2!$A$2:$B$74,MATCH(G37,Tabelle2!$B$2:$B$74,0),1)) -> WRLA-A273
A38: 5710 | B38: bairisch mit mittel- und niederdeutschen Formen | D38: Bairisch | E38: Mitteldeutsch | F38: Niederdeutsch | T38: =IF(D38="","",INDEX(Tabelle2!$A$2:$B$74,MATCH(D38,Tabelle2!$B$2:$B$74,0),1)) -> WRLA-A523 | U38: =IF(E38="","",INDEX(Tabelle2!$A$2:$B$74,MATCH(E38,Tabelle2!$B$2:$B$74,0),1)) -> WRLA-A129 | V38: =IF(F38="","",INDEX(Tabelle2!$A$2:$B$74,MATCH(F38,Tabelle2!$B$2:$B$74,0),1)) -> WRLA-A683 | W38: =IF(G38="","",INDEX(Tabelle2!$A$2:$B$74,MATCH(G38,Tabelle2!$B$2:$B$74,0),1))
A39: 5710 | B39: bairisch mit österreichischen Formen | D39: Mittel-/Südbairisch | T39: =IF(D39="","",INDEX(Tabelle2!$A$2:$B$74,MATCH(D39,Tabelle2!$B$2:$B$74,0),1)) -> WRLA-A928 | U39: =IF(E39="","",INDEX(Tabelle2!$A$2:$B$74,MATCH(E39,Tabelle2!$B$2:$B$74,0),1)) | V39: =IF(F39="","",INDEX(Tabelle2!$A$2:$B$74,MATCH(F39,Tabelle2!$B$2:$B$74,0),1)) | W39: =IF(G39="","",INDEX(Tabelle2!$A$2:$B$74,MATCH(G39,Tabelle2!$B$2:$B$74,0),1))
A40: 5710 | B40: bairisch mit schwäbischen Formen | D40: Bairisch | E40: Schwäbisch | T40: =IF(D40="","",INDEX(Tabelle2!$A$2:$B$74,MATCH(D40,Tabelle2!$B$2:$B$74,0),1)) -> WRLA-A523 | U40: =IF(E40="","",INDEX(Tabelle2!$A$2:$B$74,MATCH(E40,Tabelle2!$B$2:$B$74,0),1)) -> WRLA-A273 | V40: =IF(F40="","",INDEX(Tabelle2!$A$2:$B$74,MATCH(F40,Tabelle2!$B$2:$B$74,0),1)) | W40: =IF(G40="","",INDEX(Tabelle2!$A$2:$B$74,MATCH(G40,Tabelle2!$B$2:$B$74,0),1))
...

Sheet Tabelle2
A1: Notation | B1: Label
A2: WRLA-A506 | B2: Hochdeutsch
A3: WRLA-A538 | B3: Oberdeutsch
A4: WRLA-A317 | B4: Alemannisch
A5: WRLA-A273 | B5: Schwäbisch
A6: WRLA-A689 | B6: Westschwäbisch
A7: WRLA-A214 | B7: Zentralschwäbisch
A8: WRLA-A960 | B8: Südschwäbisch
A9: WRLA-A482 | B9: Ostschwäbisch
A10: WRLA-A638 | B10: Augsburgisch
A11: WRLA-A848 | B11: Bodenseealemannisch
A12: WRLA-A352 | B12: Oberrheinisch
... A71: WRLA-A349 | B71: Südmärkisch
